2025-07-25T22:21:07.000000000Z [info] Starting Container
2025-07-25T22:21:12.423867926Z [info] 2025-07-25 22:21:11,434 INFO sqlalchemy.engine.Engine BEGIN (implicit)
2025-07-25T22:21:12.423887041Z [error] 2025-07-25 22:21:11,434 - sqlalchemy.engine.Engine - INFO - BEGIN (implicit)
2025-07-25T22:21:12.423959654Z [info] 2025-07-25 22:21:11,439 INFO sqlalchemy.engine.Engine SELECT config_settings.id AS config_settings_id, config_settings."key" AS config_settings_key, config_settings.value AS config_settings_value, config_settings.config_type AS config_settings_config_type, config_settings.category AS config_settings_category, config_settings.scope AS config_settings_scope, config_settings.tenant_id AS config_settings_tenant_id, config_settings.user_id AS config_settings_user_id, config_settings.session_id AS config_settings_session_id, config_settings.environment AS config_settings_environment, config_settings.encrypted AS config_settings_encrypted, config_settings.description AS config_settings_description, config_settings.tags AS config_settings_tags, config_settings.created_by AS config_settings_created_by, config_settings.updated_by AS config_settings_updated_by, config_settings.created_at AS config_settings_created_at, config_settings.updated_at AS config_settings_updated_at, config_settings.version AS config_settings_version, config_settings.previous_value AS config_settings_previous_value 
2025-07-25T22:21:12.423977105Z [info] FROM config_settings
2025-07-25T22:21:12.424001920Z [info] 2025-07-25 22:21:11,439 INFO sqlalchemy.engine.Engine [generated in 0.00045s] ()
2025-07-25T22:21:12.424363185Z [error] 2025-07-25 22:21:11,439 - sqlalchemy.engine.Engine - INFO - SELECT config_settings.id AS config_settings_id, config_settings."key" AS config_settings_key, config_settings.value AS config_settings_value, config_settings.config_type AS config_settings_config_type, config_settings.category AS config_settings_category, config_settings.scope AS config_settings_scope, config_settings.tenant_id AS config_settings_tenant_id, config_settings.user_id AS config_settings_user_id, config_settings.session_id AS config_settings_session_id, config_settings.environment AS config_settings_environment, config_settings.encrypted AS config_settings_encrypted, config_settings.description AS config_settings_description, config_settings.tags AS config_settings_tags, config_settings.created_by AS config_settings_created_by, config_settings.updated_by AS config_settings_updated_by, config_settings.created_at AS config_settings_created_at, config_settings.updated_at AS config_settings_updated_at, config_settings.version AS config_settings_version, config_settings.previous_value AS config_settings_previous_value 
2025-07-25T22:21:12.424429391Z [error] FROM config_settings
2025-07-25T22:21:12.424463226Z [error] 2025-07-25 22:21:11,439 - sqlalchemy.engine.Engine - INFO - [generated in 0.00045s] ()
2025-07-25T22:21:12.424513998Z [error] 2025-07-25 22:21:11,440 - backend.app.services.config_service - ERROR - Failed to load configuration cache: (sqlite3.OperationalError) no such table: config_settings
2025-07-25T22:21:12.424579357Z [error] [SQL: SELECT config_settings.id AS config_settings_id, config_settings."key" AS config_settings_key, config_settings.value AS config_settings_value, config_settings.config_type AS config_settings_config_type, config_settings.category AS config_settings_category, config_settings.scope AS config_settings_scope, config_settings.tenant_id AS config_settings_tenant_id, config_settings.user_id AS config_settings_user_id, config_settings.session_id AS config_settings_session_id, config_settings.environment AS config_settings_environment, config_settings.encrypted AS config_settings_encrypted, config_settings.description AS config_settings_description, config_settings.tags AS config_settings_tags, config_settings.created_by AS config_settings_created_by, config_settings.updated_by AS config_settings_updated_by, config_settings.created_at AS config_settings_created_at, config_settings.updated_at AS config_settings_updated_at, config_settings.version AS config_settings_version, config_settings.previous_value AS config_settings_previous_value 
2025-07-25T22:21:12.424597464Z [error] FROM config_settings]
2025-07-25T22:21:12.424623476Z [error] (Background on this error at: https://sqlalche.me/e/20/e3q8)
2025-07-25T22:21:12.424644222Z [info] 2025-07-25 22:21:11,440 INFO sqlalchemy.engine.Engine ROLLBACK
2025-07-25T22:21:12.424667068Z [error] 2025-07-25 22:21:11,440 - sqlalchemy.engine.Engine - INFO - ROLLBACK
2025-07-25T22:21:12.424694529Z [error] Traceback (most recent call last):
2025-07-25T22:21:12.424714148Z [error]   File "<frozen runpy>", line 198, in _run_module_as_main
2025-07-25T22:21:12.424733866Z [error]   File "<frozen runpy>", line 88, in _run_code
2025-07-25T22:21:12.424756274Z [error]   File "/usr/local/lib/python3.11/site-packages/gunicorn/__main__.py", line 7, in <module>
2025-07-25T22:21:12.424772509Z [error]     run()
2025-07-25T22:21:12.424800167Z [error]   File "/usr/local/lib/python3.11/site-packages/gunicorn/app/wsgiapp.py", line 67, in run
2025-07-25T22:21:12.424819041Z [error]     WSGIApplication("%(prog)s [OPTIONS] [APP_MODULE]").run()
2025-07-25T22:21:12.424839100Z [error]   File "/usr/local/lib/python3.11/site-packages/gunicorn/app/base.py", line 236, in run
2025-07-25T22:21:12.424857436Z [error]     super().run()
2025-07-25T22:21:12.424879405Z [error]   File "/usr/local/lib/python3.11/site-packages/gunicorn/app/base.py", line 72, in run
2025-07-25T22:21:12.424900198Z [error]     Arbiter(self).run()
2025-07-25T22:21:12.424920837Z [error]     ^^^^^^^^^^^^^
2025-07-25T22:21:12.424941068Z [error]   File "/usr/local/lib/python3.11/site-packages/gunicorn/arbiter.py", line 58, in __init__
2025-07-25T22:21:12.424957431Z [error]     self.setup(app)
2025-07-25T22:21:12.424979260Z [error]   File "/usr/local/lib/python3.11/site-packages/gunicorn/arbiter.py", line 118, in setup
2025-07-25T22:21:12.424999624Z [error]     self.app.wsgi()
2025-07-25T22:21:12.425023204Z [error]   File "/usr/local/lib/python3.11/site-packages/gunicorn/app/base.py", line 67, in wsgi
2025-07-25T22:21:12.425039871Z [error]     self.callable = self.load()
2025-07-25T22:21:12.425058590Z [error]                     ^^^^^^^^^^^
2025-07-25T22:21:12.425079559Z [error]   File "/usr/local/lib/python3.11/site-packages/gunicorn/app/wsgiapp.py", line 58, in load
2025-07-25T22:21:12.425096124Z [error]     return self.load_wsgiapp()
2025-07-25T22:21:12.425118250Z [error]            ^^^^^^^^^^^^^^^^^^^
2025-07-25T22:21:12.425140082Z [error]   File "/usr/local/lib/python3.11/site-packages/gunicorn/app/wsgiapp.py", line 48, in load_wsgiapp
2025-07-25T22:21:12.425766211Z [error]     return util.import_app(self.app_uri)
2025-07-25T22:21:12.425791997Z [error]            ^^^^^^^^^^^^^^^^^^^^^^^^^^^^^
2025-07-25T22:21:12.425816796Z [error]   File "/usr/local/lib/python3.11/site-packages/gunicorn/util.py", line 371, in import_app
2025-07-25T22:21:12.425839775Z [error]     mod = importlib.import_module(module)
2025-07-25T22:21:12.425859869Z [error]           ^^^^^^^^^^^^^^^^^^^^^^^^^^^^^^^
2025-07-25T22:21:12.425897344Z [error]   File "/usr/local/lib/python3.11/importlib/__init__.py", line 126, in import_module
2025-07-25T22:21:12.425918636Z [error]     return _bootstrap._gcd_import(name[level:], package, level)
2025-07-25T22:21:12.425935791Z [error]            ^^^^^^^^^^^^^^^^^^^^^^^^^^^^^^^^^^^^^^^^^^^^^^^^^^^^
2025-07-25T22:21:12.425958462Z [error]   File "<frozen importlib._bootstrap>", line 1204, in _gcd_import
2025-07-25T22:21:12.425975081Z [error]   File "<frozen importlib._bootstrap>", line 1176, in _find_and_load
2025-07-25T22:21:12.425993221Z [error]   File "<frozen importlib._bootstrap>", line 1147, in _find_and_load_unlocked
2025-07-25T22:21:12.426011131Z [error]   File "<frozen importlib._bootstrap>", line 690, in _load_unlocked
2025-07-25T22:21:12.426042017Z [error]   File "<frozen importlib._bootstrap_external>", line 940, in exec_module
2025-07-25T22:21:12.426085588Z [error]   File "<frozen importlib._bootstrap>", line 241, in _call_with_frames_removed
2025-07-25T22:21:12.426106192Z [error]   File "/app/backend/app/main.py", line 22, in <module>
2025-07-25T22:21:12.434828022Z [error]     from .api.v1.api import api_router
2025-07-25T22:21:12.434902056Z [error]   File "/app/backend/app/api/v1/api.py", line 4, in <module>
2025-07-25T22:21:12.434941635Z [error]     from app.api import (
2025-07-25T22:21:12.434968391Z [error] ModuleNotFoundError: No module named 'app'
2025-07-25T22:21:12.434996315Z [info] Starting production server on port 8080...
2025-07-25T22:21:12.435016946Z [info] Command: python -m gunicorn backend.app.main:app -c gunicorn.conf.py
2025-07-25T22:21:12.435042224Z [info] Error starting server: Command '['python', '-m', 'gunicorn', 'backend.app.main:app', '-c', 'gunicorn.conf.py']' returned non-zero exit status 1.
2025-07-25T22:21:17.581911403Z [info] 2025-07-25 22:21:17,579 INFO sqlalchemy.engine.Engine BEGIN (implicit)
2025-07-25T22:21:17.581927476Z [error] 2025-07-25 22:21:17,579 - sqlalchemy.engine.Engine - INFO - BEGIN (implicit)
2025-07-25T22:21:17.593164864Z [info] 2025-07-25 22:21:17,588 INFO sqlalchemy.engine.Engine SELECT config_settings.id AS config_settings_id, config_settings."key" AS config_settings_key, config_settings.value AS config_settings_value, config_settings.config_type AS config_settings_config_type, config_settings.category AS config_settings_category, config_settings.scope AS config_settings_scope, config_settings.tenant_id AS config_settings_tenant_id, config_settings.user_id AS config_settings_user_id, config_settings.session_id AS config_settings_session_id, config_settings.environment AS config_settings_environment, config_settings.encrypted AS config_settings_encrypted, config_settings.description AS config_settings_description, config_settings.tags AS config_settings_tags, config_settings.created_by AS config_settings_created_by, config_settings.updated_by AS config_settings_updated_by, config_settings.created_at AS config_settings_created_at, config_settings.updated_at AS config_settings_updated_at, config_settings.version AS config_settings_version, config_settings.previous_value AS config_settings_previous_value 
2025-07-25T22:21:17.593186023Z [info] FROM config_settings
2025-07-25T22:21:17.593265206Z [error] 2025-07-25 22:21:17,588 - sqlalchemy.engine.Engine - INFO - SELECT config_settings.id AS config_settings_id, config_settings."key" AS config_settings_key, config_settings.value AS config_settings_value, config_settings.config_type AS config_settings_config_type, config_settings.category AS config_settings_category, config_settings.scope AS config_settings_scope, config_settings.tenant_id AS config_settings_tenant_id, config_settings.user_id AS config_settings_user_id, config_settings.session_id AS config_settings_session_id, config_settings.environment AS config_settings_environment, config_settings.encrypted AS config_settings_encrypted, config_settings.description AS config_settings_description, config_settings.tags AS config_settings_tags, config_settings.created_by AS config_settings_created_by, config_settings.updated_by AS config_settings_updated_by, config_settings.created_at AS config_settings_created_at, config_settings.updated_at AS config_settings_updated_at, config_settings.version AS config_settings_version, config_settings.previous_value AS config_settings_previous_value 
2025-07-25T22:21:17.594719661Z [error] FROM config_settings
2025-07-25T22:21:17.594749224Z [info] 2025-07-25 22:21:17,588 INFO sqlalchemy.engine.Engine [generated in 0.00092s] ()
2025-07-25T22:21:17.594774976Z [error] 2025-07-25 22:21:17,588 - sqlalchemy.engine.Engine - INFO - [generated in 0.00092s] ()
2025-07-25T22:21:17.594804236Z [error] 2025-07-25 22:21:17,589 - backend.app.services.config_service - ERROR - Failed to load configuration cache: (sqlite3.OperationalError) no such table: config_settings
2025-07-25T22:21:17.594936484Z [error] [SQL: SELECT config_settings.id AS config_settings_id, config_settings."key" AS config_settings_key, config_settings.value AS config_settings_value, config_settings.config_type AS config_settings_config_type, config_settings.category AS config_settings_category, config_settings.scope AS config_settings_scope, config_settings.tenant_id AS config_settings_tenant_id, config_settings.user_id AS config_settings_user_id, config_settings.session_id AS config_settings_session_id, config_settings.environment AS config_settings_environment, config_settings.encrypted AS config_settings_encrypted, config_settings.description AS config_settings_description, config_settings.tags AS config_settings_tags, config_settings.created_by AS config_settings_created_by, config_settings.updated_by AS config_settings_updated_by, config_settings.created_at AS config_settings_created_at, config_settings.updated_at AS config_settings_updated_at, config_settings.version AS config_settings_version, config_settings.previous_value AS config_settings_previous_value 
2025-07-25T22:21:17.594955962Z [error] FROM config_settings]
2025-07-25T22:21:17.595004972Z [error] (Background on this error at: https://sqlalche.me/e/20/e3q8)
2025-07-25T22:21:17.595027134Z [info] 2025-07-25 22:21:17,589 INFO sqlalchemy.engine.Engine ROLLBACK
2025-07-25T22:21:17.595052174Z [error] 2025-07-25 22:21:17,589 - sqlalchemy.engine.Engine - INFO - ROLLBACK
2025-07-25T22:21:17.723419619Z [error] Traceback (most recent call last):
2025-07-25T22:21:17.723438012Z [error]   File "<frozen runpy>", line 198, in _run_module_as_main
2025-07-25T22:21:17.723456537Z [error]   File "<frozen runpy>", line 88, in _run_code
2025-07-25T22:21:17.723475669Z [error]   File "/usr/local/lib/python3.11/site-packages/gunicorn/__main__.py", line 7, in <module>
2025-07-25T22:21:17.723493220Z [error]     run()
2025-07-25T22:21:17.723514482Z [error]   File "/usr/local/lib/python3.11/site-packages/gunicorn/app/wsgiapp.py", line 67, in run
2025-07-25T22:21:17.723533776Z [error]     WSGIApplication("%(prog)s [OPTIONS] [APP_MODULE]").run()
2025-07-25T22:21:17.723562393Z [error]   File "/usr/local/lib/python3.11/site-packages/gunicorn/app/base.py", line 236, in run
2025-07-25T22:21:17.723588279Z [error]     super().run()
2025-07-25T22:21:17.723607686Z [error]   File "/usr/local/lib/python3.11/site-packages/gunicorn/app/base.py", line 72, in run
2025-07-25T22:21:17.723776032Z [error]     Arbiter(self).run()
2025-07-25T22:21:17.723797403Z [error]     ^^^^^^^^^^^^^
2025-07-25T22:21:17.723819109Z [error]   File "/usr/local/lib/python3.11/site-packages/gunicorn/arbiter.py", line 58, in __init__
2025-07-25T22:21:17.723837620Z [error]     self.setup(app)
2025-07-25T22:21:17.725348404Z [error]   File "/usr/local/lib/python3.11/site-packages/gunicorn/arbiter.py", line 118, in setup
2025-07-25T22:21:17.725564877Z [error]     self.app.wsgi()
2025-07-25T22:21:17.725622851Z [error]   File "/usr/local/lib/python3.11/site-packages/gunicorn/app/wsgiapp.py", line 48, in load_wsgiapp
2025-07-25T22:21:17.725648266Z [error]   File "/usr/local/lib/python3.11/site-packages/gunicorn/app/base.py", line 67, in wsgi
2025-07-25T22:21:17.725652463Z [error]     return util.import_app(self.app_uri)
2025-07-25T22:21:17.725675922Z [error]            ^^^^^^^^^^^^^^^^^^^^^^^^^^^^^
2025-07-25T22:21:17.725678839Z [error]     self.callable = self.load()
2025-07-25T22:21:17.725701967Z [error]   File "/usr/local/lib/python3.11/site-packages/gunicorn/util.py", line 371, in import_app
2025-07-25T22:21:17.725724532Z [error]     mod = importlib.import_module(module)
2025-07-25T22:21:17.725746277Z [error]           ^^^^^^^^^^^^^^^^^^^^^^^^^^^^^^^
2025-07-25T22:21:17.725770897Z [error]   File "/usr/local/lib/python3.11/importlib/__init__.py", line 126, in import_module
2025-07-25T22:21:17.725794323Z [error]     return _bootstrap._gcd_import(name[level:], package, level)
2025-07-25T22:21:17.725815567Z [error]            ^^^^^^^^^^^^^^^^^^^^^^^^^^^^^^^^^^^^^^^^^^^^^^^^^^^^
2025-07-25T22:21:17.725833910Z [error]                     ^^^^^^^^^^^
2025-07-25T22:21:17.725842353Z [error]   File "<frozen importlib._bootstrap>", line 1204, in _gcd_import
2025-07-25T22:21:17.725862232Z [error]   File "/usr/local/lib/python3.11/site-packages/gunicorn/app/wsgiapp.py", line 58, in load
2025-07-25T22:21:17.725864327Z [error]   File "<frozen importlib._bootstrap>", line 1176, in _find_and_load
2025-07-25T22:21:17.725893829Z [error]   File "<frozen importlib._bootstrap>", line 1147, in _find_and_load_unlocked
2025-07-25T22:21:17.725932026Z [error]   File "<frozen importlib._bootstrap>", line 690, in _load_unlocked
2025-07-25T22:21:17.725969572Z [error]   File "<frozen importlib._bootstrap_external>", line 940, in exec_module
2025-07-25T22:21:17.725991027Z [error]   File "<frozen importlib._bootstrap>", line 241, in _call_with_frames_removed
2025-07-25T22:21:17.726015531Z [error]   File "/app/backend/app/main.py", line 22, in <module>
2025-07-25T22:21:17.726037291Z [error]     from .api.v1.api import api_router
2025-07-25T22:21:17.726147234Z [error]   File "/app/backend/app/api/v1/api.py", line 4, in <module>
2025-07-25T22:21:17.726423584Z [error]     from app.api import (
2025-07-25T22:21:17.726456899Z [error] ModuleNotFoundError: No module named 'app'
2025-07-25T22:21:17.730517976Z [error]     return self.load_wsgiapp()
2025-07-25T22:21:17.730585795Z [error]            ^^^^^^^^^^^^^^^^^^^
2025-07-25T22:21:18.566319165Z [info] Starting production server on port 8080...
2025-07-25T22:21:18.566339306Z [info] Command: python -m gunicorn backend.app.main:app -c gunicorn.conf.py
2025-07-25T22:21:18.566364500Z [info] Error starting server: Command '['python', '-m', 'gunicorn', 'backend.app.main:app', '-c', 'gunicorn.conf.py']' returned non-zero exit status 1.
2025-07-25T22:21:24.006637413Z [info] 2025-07-25 22:21:24,005 INFO sqlalchemy.engine.Engine BEGIN (implicit)
2025-07-25T22:21:24.006667236Z [error] 2025-07-25 22:21:24,005 - sqlalchemy.engine.Engine - INFO - BEGIN (implicit)
2025-07-25T22:21:24.010452314Z [error] FROM config_settings
2025-07-25T22:21:24.010486798Z [info] 2025-07-25 22:21:24,009 INFO sqlalchemy.engine.Engine [generated in 0.00027s] ()
2025-07-25T22:21:24.010509212Z [info] 2025-07-25 22:21:24,008 INFO sqlalchemy.engine.Engine SELECT config_settings.id AS config_settings_id, config_settings."key" AS config_settings_key, config_settings.value AS config_settings_value, config_settings.config_type AS config_settings_config_type, config_settings.category AS config_settings_category, config_settings.scope AS config_settings_scope, config_settings.tenant_id AS config_settings_tenant_id, config_settings.user_id AS config_settings_user_id, config_settings.session_id AS config_settings_session_id, config_settings.environment AS config_settings_environment, config_settings.encrypted AS config_settings_encrypted, config_settings.description AS config_settings_description, config_settings.tags AS config_settings_tags, config_settings.created_by AS config_settings_created_by, config_settings.updated_by AS config_settings_updated_by, config_settings.created_at AS config_settings_created_at, config_settings.updated_at AS config_settings_updated_at, config_settings.version AS config_settings_version, config_settings.previous_value AS config_settings_previous_value 
2025-07-25T22:21:24.010509916Z [error] 2025-07-25 22:21:24,009 - sqlalchemy.engine.Engine - INFO - [generated in 0.00027s] ()
2025-07-25T22:21:24.010532736Z [info] FROM config_settings
2025-07-25T22:21:24.010537947Z [error] 2025-07-25 22:21:24,009 - backend.app.services.config_service - ERROR - Failed to load configuration cache: (sqlite3.OperationalError) no such table: config_settings
2025-07-25T22:21:24.010604781Z [error] 2025-07-25 22:21:24,008 - sqlalchemy.engine.Engine - INFO - SELECT config_settings.id AS config_settings_id, config_settings."key" AS config_settings_key, config_settings.value AS config_settings_value, config_settings.config_type AS config_settings_config_type, config_settings.category AS config_settings_category, config_settings.scope AS config_settings_scope, config_settings.tenant_id AS config_settings_tenant_id, config_settings.user_id AS config_settings_user_id, config_settings.session_id AS config_settings_session_id, config_settings.environment AS config_settings_environment, config_settings.encrypted AS config_settings_encrypted, config_settings.description AS config_settings_description, config_settings.tags AS config_settings_tags, config_settings.created_by AS config_settings_created_by, config_settings.updated_by AS config_settings_updated_by, config_settings.created_at AS config_settings_created_at, config_settings.updated_at AS config_settings_updated_at, config_settings.version AS config_settings_version, config_settings.previous_value AS config_settings_previous_value 
2025-07-25T22:21:24.010644742Z [error] [SQL: SELECT config_settings.id AS config_settings_id, config_settings."key" AS config_settings_key, config_settings.value AS config_settings_value, config_settings.config_type AS config_settings_config_type, config_settings.category AS config_settings_category, config_settings.scope AS config_settings_scope, config_settings.tenant_id AS config_settings_tenant_id, config_settings.user_id AS config_settings_user_id, config_settings.session_id AS config_settings_session_id, config_settings.environment AS config_settings_environment, config_settings.encrypted AS config_settings_encrypted, config_settings.description AS config_settings_description, config_settings.tags AS config_settings_tags, config_settings.created_by AS config_settings_created_by, config_settings.updated_by AS config_settings_updated_by, config_settings.created_at AS config_settings_created_at, config_settings.updated_at AS config_settings_updated_at, config_settings.version AS config_settings_version, config_settings.previous_value AS config_settings_previous_value 
2025-07-25T22:21:24.010661638Z [error] FROM config_settings]
2025-07-25T22:21:24.010683177Z [error] (Background on this error at: https://sqlalche.me/e/20/e3q8)
2025-07-25T22:21:24.010702045Z [info] 2025-07-25 22:21:24,009 INFO sqlalchemy.engine.Engine ROLLBACK
2025-07-25T22:21:24.010721754Z [error] 2025-07-25 22:21:24,009 - sqlalchemy.engine.Engine - INFO - ROLLBACK
2025-07-25T22:21:24.090356368Z [error] Traceback (most recent call last):
2025-07-25T22:21:24.090380802Z [error]   File "<frozen runpy>", line 198, in _run_module_as_main
2025-07-25T22:21:24.090400531Z [error]   File "<frozen runpy>", line 88, in _run_code
2025-07-25T22:21:24.090422476Z [error]   File "/usr/local/lib/python3.11/site-packages/gunicorn/__main__.py", line 7, in <module>
2025-07-25T22:21:24.090441844Z [error]     run()
2025-07-25T22:21:24.090469398Z [error]   File "/usr/local/lib/python3.11/site-packages/gunicorn/app/wsgiapp.py", line 67, in run
2025-07-25T22:21:24.090489521Z [error]     WSGIApplication("%(prog)s [OPTIONS] [APP_MODULE]").run()
2025-07-25T22:21:24.090509372Z [error]   File "/usr/local/lib/python3.11/site-packages/gunicorn/app/base.py", line 236, in run
2025-07-25T22:21:24.090527875Z [error]     super().run()
2025-07-25T22:21:24.090547529Z [error]   File "/usr/local/lib/python3.11/site-packages/gunicorn/app/base.py", line 72, in run
2025-07-25T22:21:24.090565857Z [error]     Arbiter(self).run()
2025-07-25T22:21:24.090582383Z [error]     ^^^^^^^^^^^^^
2025-07-25T22:21:24.090601987Z [error]   File "/usr/local/lib/python3.11/site-packages/gunicorn/arbiter.py", line 58, in __init__
2025-07-25T22:21:24.090617677Z [error]     self.setup(app)
2025-07-25T22:21:24.090638465Z [error]   File "/usr/local/lib/python3.11/site-packages/gunicorn/arbiter.py", line 118, in setup
2025-07-25T22:21:24.090656501Z [error]     self.app.wsgi()
2025-07-25T22:21:24.090677904Z [error]   File "/usr/local/lib/python3.11/site-packages/gunicorn/app/base.py", line 67, in wsgi
2025-07-25T22:21:24.090695833Z [error]     self.callable = self.load()
2025-07-25T22:21:24.090712718Z [error]                     ^^^^^^^^^^^
2025-07-25T22:21:24.090734620Z [error]   File "/usr/local/lib/python3.11/site-packages/gunicorn/app/wsgiapp.py", line 58, in load
2025-07-25T22:21:24.090755114Z [error]     return self.load_wsgiapp()
2025-07-25T22:21:24.090775733Z [error]            ^^^^^^^^^^^^^^^^^^^
2025-07-25T22:21:24.090802043Z [error]   File "/usr/local/lib/python3.11/site-packages/gunicorn/app/wsgiapp.py", line 48, in load_wsgiapp
2025-07-25T22:21:24.090818079Z [error]     return util.import_app(self.app_uri)
2025-07-25T22:21:24.090835234Z [error]            ^^^^^^^^^^^^^^^^^^^^^^^^^^^^^
2025-07-25T22:21:24.090857206Z [error]   File "/usr/local/lib/python3.11/site-packages/gunicorn/util.py", line 371, in import_app
2025-07-25T22:21:24.090879964Z [error]     mod = importlib.import_module(module)
2025-07-25T22:21:24.090896721Z [error]           ^^^^^^^^^^^^^^^^^^^^^^^^^^^^^^^
2025-07-25T22:21:24.090914931Z [error]   File "/usr/local/lib/python3.11/importlib/__init__.py", line 126, in import_module
2025-07-25T22:21:24.090932748Z [error]     return _bootstrap._gcd_import(name[level:], package, level)
2025-07-25T22:21:24.090958735Z [error]            ^^^^^^^^^^^^^^^^^^^^^^^^^^^^^^^^^^^^^^^^^^^^^^^^^^^^
2025-07-25T22:21:24.090977859Z [error]   File "<frozen importlib._bootstrap>", line 1204, in _gcd_import
2025-07-25T22:21:24.091000233Z [error]   File "<frozen importlib._bootstrap>", line 1176, in _find_and_load
2025-07-25T22:21:24.091018370Z [error]   File "<frozen importlib._bootstrap>", line 1147, in _find_and_load_unlocked
2025-07-25T22:21:24.091036167Z [error]   File "<frozen importlib._bootstrap>", line 690, in _load_unlocked
2025-07-25T22:21:24.091057759Z [error]   File "<frozen importlib._bootstrap_external>", line 940, in exec_module
2025-07-25T22:21:24.091077719Z [error]   File "<frozen importlib._bootstrap>", line 241, in _call_with_frames_removed
2025-07-25T22:21:24.091099540Z [error]   File "/app/backend/app/main.py", line 22, in <module>
2025-07-25T22:21:24.091115811Z [error]     from .api.v1.api import api_router
2025-07-25T22:21:24.091330454Z [error]   File "/app/backend/app/api/v1/api.py", line 4, in <module>
2025-07-25T22:21:24.091365836Z [error]     from app.api import (
2025-07-25T22:21:24.091395176Z [error] ModuleNotFoundError: No module named 'app'
2025-07-25T22:21:24.800206083Z [info] Starting production server on port 8080...
2025-07-25T22:21:24.800228716Z [info] Command: python -m gunicorn backend.app.main:app -c gunicorn.conf.py
2025-07-25T22:21:24.800309491Z [info] Error starting server: Command '['python', '-m', 'gunicorn', 'backend.app.main:app', '-c', 'gunicorn.conf.py']' returned non-zero exit status 1.
2025-07-25T22:21:30.499002622Z [info] 2025-07-25 22:21:30,494 INFO sqlalchemy.engine.Engine BEGIN (implicit)
2025-07-25T22:21:30.499032003Z [error] 2025-07-25 22:21:30,494 - sqlalchemy.engine.Engine - INFO - BEGIN (implicit)
2025-07-25T22:21:30.503429677Z [error] FROM config_settings
2025-07-25T22:21:30.503463452Z [info] 2025-07-25 22:21:30,500 INFO sqlalchemy.engine.Engine [generated in 0.00048s] ()
2025-07-25T22:21:30.503484753Z [error] 2025-07-25 22:21:30,500 - sqlalchemy.engine.Engine - INFO - [generated in 0.00048s] ()
2025-07-25T22:21:30.503511191Z [error] 2025-07-25 22:21:30,500 - backend.app.services.config_service - ERROR - Failed to load configuration cache: (sqlite3.OperationalError) no such table: config_settings
2025-07-25T22:21:30.503596863Z [info] 2025-07-25 22:21:30,500 INFO sqlalchemy.engine.Engine SELECT config_settings.id AS config_settings_id, config_settings."key" AS config_settings_key, config_settings.value AS config_settings_value, config_settings.config_type AS config_settings_config_type, config_settings.category AS config_settings_category, config_settings.scope AS config_settings_scope, config_settings.tenant_id AS config_settings_tenant_id, config_settings.user_id AS config_settings_user_id, config_settings.session_id AS config_settings_session_id, config_settings.environment AS config_settings_environment, config_settings.encrypted AS config_settings_encrypted, config_settings.description AS config_settings_description, config_settings.tags AS config_settings_tags, config_settings.created_by AS config_settings_created_by, config_settings.updated_by AS config_settings_updated_by, config_settings.created_at AS config_settings_created_at, config_settings.updated_at AS config_settings_updated_at, config_settings.version AS config_settings_version, config_settings.previous_value AS config_settings_previous_value 
2025-07-25T22:21:30.503600039Z [error] [SQL: SELECT config_settings.id AS config_settings_id, config_settings."key" AS config_settings_key, config_settings.value AS config_settings_value, config_settings.config_type AS config_settings_config_type, config_settings.category AS config_settings_category, config_settings.scope AS config_settings_scope, config_settings.tenant_id AS config_settings_tenant_id, config_settings.user_id AS config_settings_user_id, config_settings.session_id AS config_settings_session_id, config_settings.environment AS config_settings_environment, config_settings.encrypted AS config_settings_encrypted, config_settings.description AS config_settings_description, config_settings.tags AS config_settings_tags, config_settings.created_by AS config_settings_created_by, config_settings.updated_by AS config_settings_updated_by, config_settings.created_at AS config_settings_created_at, config_settings.updated_at AS config_settings_updated_at, config_settings.version AS config_settings_version, config_settings.previous_value AS config_settings_previous_value 
2025-07-25T22:21:30.503618018Z [info] FROM config_settings
2025-07-25T22:21:30.503627207Z [error] FROM config_settings]
2025-07-25T22:21:30.503650472Z [error] (Background on this error at: https://sqlalche.me/e/20/e3q8)
2025-07-25T22:21:30.503672135Z [info] 2025-07-25 22:21:30,501 INFO sqlalchemy.engine.Engine ROLLBACK
2025-07-25T22:21:30.503678594Z [error] 2025-07-25 22:21:30,500 - sqlalchemy.engine.Engine - INFO - SELECT config_settings.id AS config_settings_id, config_settings."key" AS config_settings_key, config_settings.value AS config_settings_value, config_settings.config_type AS config_settings_config_type, config_settings.category AS config_settings_category, config_settings.scope AS config_settings_scope, config_settings.tenant_id AS config_settings_tenant_id, config_settings.user_id AS config_settings_user_id, config_settings.session_id AS config_settings_session_id, config_settings.environment AS config_settings_environment, config_settings.encrypted AS config_settings_encrypted, config_settings.description AS config_settings_description, config_settings.tags AS config_settings_tags, config_settings.created_by AS config_settings_created_by, config_settings.updated_by AS config_settings_updated_by, config_settings.created_at AS config_settings_created_at, config_settings.updated_at AS config_settings_updated_at, config_settings.version AS config_settings_version, config_settings.previous_value AS config_settings_previous_value 
2025-07-25T22:21:30.503692839Z [error] 2025-07-25 22:21:30,501 - sqlalchemy.engine.Engine - INFO - ROLLBACK
2025-07-25T22:21:30.590872024Z [error] Traceback (most recent call last):
2025-07-25T22:21:30.590909086Z [error]   File "<frozen runpy>", line 198, in _run_module_as_main
2025-07-25T22:21:30.590957132Z [error]   File "<frozen runpy>", line 88, in _run_code
2025-07-25T22:21:30.590982810Z [error]   File "/usr/local/lib/python3.11/site-packages/gunicorn/__main__.py", line 7, in <module>
2025-07-25T22:21:30.591001448Z [error]     run()
2025-07-25T22:21:30.591025165Z [error]   File "/usr/local/lib/python3.11/site-packages/gunicorn/app/wsgiapp.py", line 67, in run
2025-07-25T22:21:30.591048012Z [error]     WSGIApplication("%(prog)s [OPTIONS] [APP_MODULE]").run()
2025-07-25T22:21:30.591071505Z [error]   File "/usr/local/lib/python3.11/site-packages/gunicorn/app/base.py", line 236, in run
2025-07-25T22:21:30.591091778Z [error]     super().run()
2025-07-25T22:21:30.591116043Z [error]   File "/usr/local/lib/python3.11/site-packages/gunicorn/app/base.py", line 72, in run
2025-07-25T22:21:30.591139343Z [error]     Arbiter(self).run()
2025-07-25T22:21:30.591159599Z [error]     ^^^^^^^^^^^^^
2025-07-25T22:21:30.591180074Z [error]   File "/usr/local/lib/python3.11/site-packages/gunicorn/arbiter.py", line 58, in __init__
2025-07-25T22:21:30.591204017Z [error]     self.setup(app)
2025-07-25T22:21:30.591225784Z [error]   File "/usr/local/lib/python3.11/site-packages/gunicorn/arbiter.py", line 118, in setup
2025-07-25T22:21:30.591243056Z [error]     self.app.wsgi()
2025-07-25T22:21:30.591272125Z [error]   File "/usr/local/lib/python3.11/site-packages/gunicorn/app/base.py", line 67, in wsgi
2025-07-25T22:21:30.591294002Z [error]     self.callable = self.load()
2025-07-25T22:21:30.591315746Z [error]                     ^^^^^^^^^^^
2025-07-25T22:21:30.591337798Z [error]   File "/usr/local/lib/python3.11/site-packages/gunicorn/app/wsgiapp.py", line 58, in load
2025-07-25T22:21:30.591358017Z [error]     return self.load_wsgiapp()
2025-07-25T22:21:30.591375768Z [error]            ^^^^^^^^^^^^^^^^^^^
2025-07-25T22:21:30.591395115Z [error]   File "/usr/local/lib/python3.11/site-packages/gunicorn/app/wsgiapp.py", line 48, in load_wsgiapp
2025-07-25T22:21:30.591416414Z [error]     return util.import_app(self.app_uri)
2025-07-25T22:21:30.591434446Z [error]            ^^^^^^^^^^^^^^^^^^^^^^^^^^^^^
2025-07-25T22:21:30.591458048Z [error]   File "/usr/local/lib/python3.11/site-packages/gunicorn/util.py", line 371, in import_app
2025-07-25T22:21:30.591484667Z [error]     mod = importlib.import_module(module)
2025-07-25T22:21:30.591504189Z [error]           ^^^^^^^^^^^^^^^^^^^^^^^^^^^^^^^
2025-07-25T22:21:30.591537946Z [error]   File "/usr/local/lib/python3.11/importlib/__init__.py", line 126, in import_module
2025-07-25T22:21:30.591573544Z [error]     return _bootstrap._gcd_import(name[level:], package, level)
2025-07-25T22:21:30.591593023Z [error]            ^^^^^^^^^^^^^^^^^^^^^^^^^^^^^^^^^^^^^^^^^^^^^^^^^^^^
2025-07-25T22:21:30.591620100Z [error]   File "<frozen importlib._bootstrap>", line 1204, in _gcd_import
2025-07-25T22:21:30.591648534Z [error]   File "<frozen importlib._bootstrap>", line 1176, in _find_and_load
2025-07-25T22:21:30.591690820Z [error]   File "<frozen importlib._bootstrap>", line 1147, in _find_and_load_unlocked
2025-07-25T22:21:30.591715945Z [error]   File "<frozen importlib._bootstrap>", line 690, in _load_unlocked
2025-07-25T22:21:30.591739171Z [error]   File "<frozen importlib._bootstrap_external>", line 940, in exec_module
2025-07-25T22:21:30.591760701Z [error]   File "<frozen importlib._bootstrap>", line 241, in _call_with_frames_removed
2025-07-25T22:21:30.591788840Z [error]   File "/app/backend/app/main.py", line 22, in <module>
2025-07-25T22:21:30.591811822Z [error]     from .api.v1.api import api_router
2025-07-25T22:21:30.591842335Z [error]   File "/app/backend/app/api/v1/api.py", line 4, in <module>
2025-07-25T22:21:30.591859339Z [error]     from app.api import (
2025-07-25T22:21:30.591880660Z [error] ModuleNotFoundError: No module named 'app'
2025-07-25T22:21:31.301018148Z [info] Starting production server on port 8080...
2025-07-25T22:21:31.301040843Z [info] Command: python -m gunicorn backend.app.main:app -c gunicorn.conf.py
2025-07-25T22:21:31.301064165Z [info] Error starting server: Command '['python', '-m', 'gunicorn', 'backend.app.main:app', '-c', 'gunicorn.conf.py']' returned non-zero exit status 1.
2025-07-25T22:21:36.848591210Z [info] 2025-07-25 22:21:36,846 INFO sqlalchemy.engine.Engine BEGIN (implicit)
2025-07-25T22:21:36.848622962Z [error] 2025-07-25 22:21:36,846 - sqlalchemy.engine.Engine - INFO - BEGIN (implicit)
2025-07-25T22:21:36.855691266Z [info] 2025-07-25 22:21:36,853 INFO sqlalchemy.engine.Engine SELECT config_settings.id AS config_settings_id, config_settings."key" AS config_settings_key, config_settings.value AS config_settings_value, config_settings.config_type AS config_settings_config_type, config_settings.category AS config_settings_category, config_settings.scope AS config_settings_scope, config_settings.tenant_id AS config_settings_tenant_id, config_settings.user_id AS config_settings_user_id, config_settings.session_id AS config_settings_session_id, config_settings.environment AS config_settings_environment, config_settings.encrypted AS config_settings_encrypted, config_settings.description AS config_settings_description, config_settings.tags AS config_settings_tags, config_settings.created_by AS config_settings_created_by, config_settings.updated_by AS config_settings_updated_by, config_settings.created_at AS config_settings_created_at, config_settings.updated_at AS config_settings_updated_at, config_settings.version AS config_settings_version, config_settings.previous_value AS config_settings_previous_value 
2025-07-25T22:21:36.855719728Z [info] FROM config_settings
2025-07-25T22:21:36.855785340Z [error] 2025-07-25 22:21:36,853 - sqlalchemy.engine.Engine - INFO - SELECT config_settings.id AS config_settings_id, config_settings."key" AS config_settings_key, config_settings.value AS config_settings_value, config_settings.config_type AS config_settings_config_type, config_settings.category AS config_settings_category, config_settings.scope AS config_settings_scope, config_settings.tenant_id AS config_settings_tenant_id, config_settings.user_id AS config_settings_user_id, config_settings.session_id AS config_settings_session_id, config_settings.environment AS config_settings_environment, config_settings.encrypted AS config_settings_encrypted, config_settings.description AS config_settings_description, config_settings.tags AS config_settings_tags, config_settings.created_by AS config_settings_created_by, config_settings.updated_by AS config_settings_updated_by, config_settings.created_at AS config_settings_created_at, config_settings.updated_at AS config_settings_updated_at, config_settings.version AS config_settings_version, config_settings.previous_value AS config_settings_previous_value 
2025-07-25T22:21:36.856506580Z [error] FROM config_settings
2025-07-25T22:21:36.856539433Z [info] 2025-07-25 22:21:36,854 INFO sqlalchemy.engine.Engine [generated in 0.00055s] ()
2025-07-25T22:21:36.856564933Z [error] 2025-07-25 22:21:36,854 - sqlalchemy.engine.Engine - INFO - [generated in 0.00055s] ()
2025-07-25T22:21:36.857442975Z [error] 2025-07-25 22:21:36,855 - backend.app.services.config_service - ERROR - Failed to load configuration cache: (sqlite3.OperationalError) no such table: config_settings
2025-07-25T22:21:36.857571671Z [error] [SQL: SELECT config_settings.id AS config_settings_id, config_settings."key" AS config_settings_key, config_settings.value AS config_settings_value, config_settings.config_type AS config_settings_config_type, config_settings.category AS config_settings_category, config_settings.scope AS config_settings_scope, config_settings.tenant_id AS config_settings_tenant_id, config_settings.user_id AS config_settings_user_id, config_settings.session_id AS config_settings_session_id, config_settings.environment AS config_settings_environment, config_settings.encrypted AS config_settings_encrypted, config_settings.description AS config_settings_description, config_settings.tags AS config_settings_tags, config_settings.created_by AS config_settings_created_by, config_settings.updated_by AS config_settings_updated_by, config_settings.created_at AS config_settings_created_at, config_settings.updated_at AS config_settings_updated_at, config_settings.version AS config_settings_version, config_settings.previous_value AS config_settings_previous_value 
2025-07-25T22:21:36.857596951Z [error] FROM config_settings]
2025-07-25T22:21:36.857624602Z [error] (Background on this error at: https://sqlalche.me/e/20/e3q8)
2025-07-25T22:21:36.857654301Z [info] 2025-07-25 22:21:36,855 INFO sqlalchemy.engine.Engine ROLLBACK
2025-07-25T22:21:36.857679165Z [error] 2025-07-25 22:21:36,855 - sqlalchemy.engine.Engine - INFO - ROLLBACK
2025-07-25T22:21:36.972203681Z [error] Traceback (most recent call last):
2025-07-25T22:21:36.972231224Z [error]   File "<frozen runpy>", line 198, in _run_module_as_main
2025-07-25T22:21:36.972250417Z [error]   File "<frozen runpy>", line 88, in _run_code
2025-07-25T22:21:36.972273030Z [error]   File "/usr/local/lib/python3.11/site-packages/gunicorn/__main__.py", line 7, in <module>
2025-07-25T22:21:36.972289599Z [error]     run()
2025-07-25T22:21:36.972312899Z [error]   File "/usr/local/lib/python3.11/site-packages/gunicorn/app/wsgiapp.py", line 67, in run
2025-07-25T22:21:36.972332997Z [error]     WSGIApplication("%(prog)s [OPTIONS] [APP_MODULE]").run()
2025-07-25T22:21:36.972354654Z [error]   File "/usr/local/lib/python3.11/site-packages/gunicorn/app/base.py", line 236, in run
2025-07-25T22:21:36.972376312Z [error]     super().run()
2025-07-25T22:21:36.972397109Z [error]   File "/usr/local/lib/python3.11/site-packages/gunicorn/app/base.py", line 72, in run
2025-07-25T22:21:36.972417227Z [error]     Arbiter(self).run()
2025-07-25T22:21:36.972441079Z [error]     ^^^^^^^^^^^^^
2025-07-25T22:21:36.972464379Z [error]   File "/usr/local/lib/python3.11/site-packages/gunicorn/arbiter.py", line 58, in __init__
2025-07-25T22:21:36.972486689Z [error]     self.setup(app)
2025-07-25T22:21:36.972597735Z [error]   File "/usr/local/lib/python3.11/site-packages/gunicorn/arbiter.py", line 118, in setup
2025-07-25T22:21:36.972795814Z [error]     self.app.wsgi()
2025-07-25T22:21:36.972828142Z [error]   File "/usr/local/lib/python3.11/site-packages/gunicorn/app/base.py", line 67, in wsgi
2025-07-25T22:21:36.972849771Z [error]     self.callable = self.load()
2025-07-25T22:21:36.972866773Z [error]                     ^^^^^^^^^^^
2025-07-25T22:21:36.972887270Z [error]   File "/usr/local/lib/python3.11/site-packages/gunicorn/app/wsgiapp.py", line 58, in load
2025-07-25T22:21:36.972907769Z [error]     return self.load_wsgiapp()
2025-07-25T22:21:36.972932699Z [error]            ^^^^^^^^^^^^^^^^^^^
2025-07-25T22:21:36.973390478Z [error]   File "/usr/local/lib/python3.11/site-packages/gunicorn/app/wsgiapp.py", line 48, in load_wsgiapp
2025-07-25T22:21:36.973411414Z [error]     return util.import_app(self.app_uri)
2025-07-25T22:21:36.973450119Z [error]            ^^^^^^^^^^^^^^^^^^^^^^^^^^^^^
2025-07-25T22:21:36.973472423Z [error]   File "/usr/local/lib/python3.11/site-packages/gunicorn/util.py", line 371, in import_app
2025-07-25T22:21:36.973509127Z [error]     mod = importlib.import_module(module)
2025-07-25T22:21:36.973533233Z [error]           ^^^^^^^^^^^^^^^^^^^^^^^^^^^^^^^
2025-07-25T22:21:36.973557475Z [error]   File "/usr/local/lib/python3.11/importlib/__init__.py", line 126, in import_module
2025-07-25T22:21:36.973578323Z [error]     return _bootstrap._gcd_import(name[level:], package, level)
2025-07-25T22:21:36.973677757Z [error]            ^^^^^^^^^^^^^^^^^^^^^^^^^^^^^^^^^^^^^^^^^^^^^^^^^^^^
2025-07-25T22:21:36.973701435Z [error]   File "<frozen importlib._bootstrap>", line 1204, in _gcd_import
2025-07-25T22:21:36.973723286Z [error]   File "<frozen importlib._bootstrap>", line 1176, in _find_and_load
2025-07-25T22:21:36.973745001Z [error]   File "<frozen importlib._bootstrap>", line 1147, in _find_and_load_unlocked
2025-07-25T22:21:36.973813834Z [error]   File "<frozen importlib._bootstrap>", line 690, in _load_unlocked
2025-07-25T22:21:36.973835157Z [error]   File "<frozen importlib._bootstrap_external>", line 940, in exec_module
2025-07-25T22:21:36.973858665Z [error]   File "<frozen importlib._bootstrap>", line 241, in _call_with_frames_removed
2025-07-25T22:21:36.973906936Z [error]   File "/app/backend/app/main.py", line 22, in <module>
2025-07-25T22:21:36.973930032Z [error]     from .api.v1.api import api_router
2025-07-25T22:21:36.973951008Z [error]   File "/app/backend/app/api/v1/api.py", line 4, in <module>
2025-07-25T22:21:36.973968912Z [error]     from app.api import (
2025-07-25T22:21:36.973991184Z [error] ModuleNotFoundError: No module named 'app'
2025-07-25T22:21:37.764377220Z [info] Starting production server on port 8080...
2025-07-25T22:21:37.764410546Z [info] Command: python -m gunicorn backend.app.main:app -c gunicorn.conf.py
2025-07-25T22:21:37.764438794Z [info] Error starting server: Command '['python', '-m', 'gunicorn', 'backend.app.main:app', '-c', 'gunicorn.conf.py']' returned non-zero exit status 1.
2025-07-25T22:21:43.167072012Z [info] 2025-07-25 22:21:43,139 INFO sqlalchemy.engine.Engine BEGIN (implicit)
2025-07-25T22:21:43.167109922Z [error] FROM config_settings
2025-07-25T22:21:43.167149396Z [error] 2025-07-25 22:21:43,144 - sqlalchemy.engine.Engine - INFO - [generated in 0.00040s] ()
2025-07-25T22:21:43.167158631Z [info] 2025-07-25 22:21:43,144 INFO sqlalchemy.engine.Engine SELECT config_settings.id AS config_settings_id, config_settings."key" AS config_settings_key, config_settings.value AS config_settings_value, config_settings.config_type AS config_settings_config_type, config_settings.category AS config_settings_category, config_settings.scope AS config_settings_scope, config_settings.tenant_id AS config_settings_tenant_id, config_settings.user_id AS config_settings_user_id, config_settings.session_id AS config_settings_session_id, config_settings.environment AS config_settings_environment, config_settings.encrypted AS config_settings_encrypted, config_settings.description AS config_settings_description, config_settings.tags AS config_settings_tags, config_settings.created_by AS config_settings_created_by, config_settings.updated_by AS config_settings_updated_by, config_settings.created_at AS config_settings_created_at, config_settings.updated_at AS config_settings_updated_at, config_settings.version AS config_settings_version, config_settings.previous_value AS config_settings_previous_value 
2025-07-25T22:21:43.167178210Z [info] FROM config_settings
2025-07-25T22:21:43.167184004Z [error] 2025-07-25 22:21:43,145 - backend.app.services.config_service - ERROR - Failed to load configuration cache: (sqlite3.OperationalError) no such table: config_settings
2025-07-25T22:21:43.167205615Z [info] 2025-07-25 22:21:43,144 INFO sqlalchemy.engine.Engine [generated in 0.00040s] ()
2025-07-25T22:21:43.167230021Z [info] 2025-07-25 22:21:43,146 INFO sqlalchemy.engine.Engine ROLLBACK
2025-07-25T22:21:43.167255850Z [error] 2025-07-25 22:21:43,139 - sqlalchemy.engine.Engine - INFO - BEGIN (implicit)
2025-07-25T22:21:43.167289173Z [error] [SQL: SELECT config_settings.id AS config_settings_id, config_settings."key" AS config_settings_key, config_settings.value AS config_settings_value, config_settings.config_type AS config_settings_config_type, config_settings.category AS config_settings_category, config_settings.scope AS config_settings_scope, config_settings.tenant_id AS config_settings_tenant_id, config_settings.user_id AS config_settings_user_id, config_settings.session_id AS config_settings_session_id, config_settings.environment AS config_settings_environment, config_settings.encrypted AS config_settings_encrypted, config_settings.description AS config_settings_description, config_settings.tags AS config_settings_tags, config_settings.created_by AS config_settings_created_by, config_settings.updated_by AS config_settings_updated_by, config_settings.created_at AS config_settings_created_at, config_settings.updated_at AS config_settings_updated_at, config_settings.version AS config_settings_version, config_settings.previous_value AS config_settings_previous_value 
2025-07-25T22:21:43.167310941Z [error] FROM config_settings]
2025-07-25T22:21:43.167342587Z [error] 2025-07-25 22:21:43,144 - sqlalchemy.engine.Engine - INFO - SELECT config_settings.id AS config_settings_id, config_settings."key" AS config_settings_key, config_settings.value AS config_settings_value, config_settings.config_type AS config_settings_config_type, config_settings.category AS config_settings_category, config_settings.scope AS config_settings_scope, config_settings.tenant_id AS config_settings_tenant_id, config_settings.user_id AS config_settings_user_id, config_settings.session_id AS config_settings_session_id, config_settings.environment AS config_settings_environment, config_settings.encrypted AS config_settings_encrypted, config_settings.description AS config_settings_description, config_settings.tags AS config_settings_tags, config_settings.created_by AS config_settings_created_by, config_settings.updated_by AS config_settings_updated_by, config_settings.created_at AS config_settings_created_at, config_settings.updated_at AS config_settings_updated_at, config_settings.version AS config_settings_version, config_settings.previous_value AS config_settings_previous_value 
2025-07-25T22:21:43.167352957Z [error] (Background on this error at: https://sqlalche.me/e/20/e3q8)
2025-07-25T22:21:43.167377754Z [error] 2025-07-25 22:21:43,146 - sqlalchemy.engine.Engine - INFO - ROLLBACK
2025-07-25T22:21:43.316278643Z [error] Traceback (most recent call last):
2025-07-25T22:21:43.316297063Z [error]   File "<frozen runpy>", line 198, in _run_module_as_main
2025-07-25T22:21:43.316315645Z [error]   File "<frozen runpy>", line 88, in _run_code
2025-07-25T22:21:43.316335581Z [error]   File "/usr/local/lib/python3.11/site-packages/gunicorn/__main__.py", line 7, in <module>
2025-07-25T22:21:43.316350229Z [error]     run()
2025-07-25T22:21:43.316375565Z [error]   File "/usr/local/lib/python3.11/site-packages/gunicorn/app/wsgiapp.py", line 67, in run
2025-07-25T22:21:43.316394600Z [error]     WSGIApplication("%(prog)s [OPTIONS] [APP_MODULE]").run()
2025-07-25T22:21:43.316415412Z [error]   File "/usr/local/lib/python3.11/site-packages/gunicorn/app/base.py", line 236, in run
2025-07-25T22:21:43.316433733Z [error]     super().run()
2025-07-25T22:21:43.316453645Z [error]   File "/usr/local/lib/python3.11/site-packages/gunicorn/app/base.py", line 72, in run
2025-07-25T22:21:43.316468899Z [error]     Arbiter(self).run()
2025-07-25T22:21:43.316486044Z [error]     ^^^^^^^^^^^^^
2025-07-25T22:21:43.316505361Z [error]   File "/usr/local/lib/python3.11/site-packages/gunicorn/arbiter.py", line 58, in __init__
2025-07-25T22:21:43.316519306Z [error]     self.setup(app)
2025-07-25T22:21:43.316552536Z [error]   File "/usr/local/lib/python3.11/site-packages/gunicorn/arbiter.py", line 118, in setup
2025-07-25T22:21:43.316567294Z [error]     self.app.wsgi()
2025-07-25T22:21:43.316586347Z [error]   File "/usr/local/lib/python3.11/site-packages/gunicorn/app/base.py", line 67, in wsgi
2025-07-25T22:21:43.316602357Z [error]     self.callable = self.load()
2025-07-25T22:21:43.316618306Z [error]                     ^^^^^^^^^^^
2025-07-25T22:21:43.316635198Z [error]   File "/usr/local/lib/python3.11/site-packages/gunicorn/app/wsgiapp.py", line 58, in load
2025-07-25T22:21:43.316651307Z [error]     return self.load_wsgiapp()
2025-07-25T22:21:43.316666327Z [error]            ^^^^^^^^^^^^^^^^^^^
2025-07-25T22:21:43.316911187Z [error]   File "/usr/local/lib/python3.11/site-packages/gunicorn/app/wsgiapp.py", line 48, in load_wsgiapp
2025-07-25T22:21:43.316927537Z [error]     return util.import_app(self.app_uri)
2025-07-25T22:21:43.316944479Z [error]            ^^^^^^^^^^^^^^^^^^^^^^^^^^^^^
2025-07-25T22:21:43.316963871Z [error]   File "/usr/local/lib/python3.11/site-packages/gunicorn/util.py", line 371, in import_app
2025-07-25T22:21:43.316980310Z [error]     mod = importlib.import_module(module)
2025-07-25T22:21:43.317001080Z [error]           ^^^^^^^^^^^^^^^^^^^^^^^^^^^^^^^
2025-07-25T22:21:43.317020202Z [error]   File "/usr/local/lib/python3.11/importlib/__init__.py", line 126, in import_module
2025-07-25T22:21:43.317038941Z [error]     return _bootstrap._gcd_import(name[level:], package, level)
2025-07-25T22:21:43.317059159Z [error]            ^^^^^^^^^^^^^^^^^^^^^^^^^^^^^^^^^^^^^^^^^^^^^^^^^^^^
2025-07-25T22:21:43.317077866Z [error]   File "<frozen importlib._bootstrap>", line 1204, in _gcd_import
2025-07-25T22:21:43.317097641Z [error]   File "<frozen importlib._bootstrap>", line 1176, in _find_and_load
2025-07-25T22:21:43.317118242Z [error]   File "<frozen importlib._bootstrap>", line 1147, in _find_and_load_unlocked
2025-07-25T22:21:43.317138342Z [error]   File "<frozen importlib._bootstrap>", line 690, in _load_unlocked
2025-07-25T22:21:43.317159268Z [error]   File "<frozen importlib._bootstrap_external>", line 940, in exec_module
2025-07-25T22:21:43.317179500Z [error]   File "<frozen importlib._bootstrap>", line 241, in _call_with_frames_removed
2025-07-25T22:21:43.317198885Z [error]   File "/app/backend/app/main.py", line 22, in <module>
2025-07-25T22:21:43.317220293Z [error]     from .api.v1.api import api_router
2025-07-25T22:21:43.317239527Z [error]   File "/app/backend/app/api/v1/api.py", line 4, in <module>
2025-07-25T22:21:43.317258134Z [error]     from app.api import (
2025-07-25T22:21:43.317272197Z [error] ModuleNotFoundError: No module named 'app'
2025-07-25T22:21:44.004033873Z [info] Starting production server on port 8080...
2025-07-25T22:21:44.004056068Z [info] Command: python -m gunicorn backend.app.main:app -c gunicorn.conf.py
2025-07-25T22:21:44.004083022Z [info] Error starting server: Command '['python', '-m', 'gunicorn', 'backend.app.main:app', '-c', 'gunicorn.conf.py']' returned non-zero exit status 1.
2025-07-25T22:21:50.003601869Z [info] 2025-07-25 22:21:50,001 INFO sqlalchemy.engine.Engine BEGIN (implicit)
2025-07-25T22:21:50.003636879Z [error] 2025-07-25 22:21:50,001 - sqlalchemy.engine.Engine - INFO - BEGIN (implicit)
2025-07-25T22:21:50.007857844Z [error] FROM config_settings
2025-07-25T22:21:50.007889544Z [error] 2025-07-25 22:21:50,006 - sqlalchemy.engine.Engine - INFO - [generated in 0.00039s] ()
2025-07-25T22:21:50.008099646Z [info] 2025-07-25 22:21:50,006 INFO sqlalchemy.engine.Engine SELECT config_settings.id AS config_settings_id, config_settings."key" AS config_settings_key, config_settings.value AS config_settings_value, config_settings.config_type AS config_settings_config_type, config_settings.category AS config_settings_category, config_settings.scope AS config_settings_scope, config_settings.tenant_id AS config_settings_tenant_id, config_settings.user_id AS config_settings_user_id, config_settings.session_id AS config_settings_session_id, config_settings.environment AS config_settings_environment, config_settings.encrypted AS config_settings_encrypted, config_settings.description AS config_settings_description, config_settings.tags AS config_settings_tags, config_settings.created_by AS config_settings_created_by, config_settings.updated_by AS config_settings_updated_by, config_settings.created_at AS config_settings_created_at, config_settings.updated_at AS config_settings_updated_at, config_settings.version AS config_settings_version, config_settings.previous_value AS config_settings_previous_value 
2025-07-25T22:21:50.008126027Z [info] FROM config_settings
2025-07-25T22:21:50.008147062Z [info] 2025-07-25 22:21:50,006 INFO sqlalchemy.engine.Engine [generated in 0.00039s] ()
2025-07-25T22:21:50.008219291Z [error] 2025-07-25 22:21:50,006 - sqlalchemy.engine.Engine - INFO - SELECT config_settings.id AS config_settings_id, config_settings."key" AS config_settings_key, config_settings.value AS config_settings_value, config_settings.config_type AS config_settings_config_type, config_settings.category AS config_settings_category, config_settings.scope AS config_settings_scope, config_settings.tenant_id AS config_settings_tenant_id, config_settings.user_id AS config_settings_user_id, config_settings.session_id AS config_settings_session_id, config_settings.environment AS config_settings_environment, config_settings.encrypted AS config_settings_encrypted, config_settings.description AS config_settings_description, config_settings.tags AS config_settings_tags, config_settings.created_by AS config_settings_created_by, config_settings.updated_by AS config_settings_updated_by, config_settings.created_at AS config_settings_created_at, config_settings.updated_at AS config_settings_updated_at, config_settings.version AS config_settings_version, config_settings.previous_value AS config_settings_previous_value 
2025-07-25T22:21:50.011340236Z [error] 2025-07-25 22:21:50,007 - backend.app.services.config_service - ERROR - Failed to load configuration cache: (sqlite3.OperationalError) no such table: config_settings
2025-07-25T22:21:50.011433055Z [error] [SQL: SELECT config_settings.id AS config_settings_id, config_settings."key" AS config_settings_key, config_settings.value AS config_settings_value, config_settings.config_type AS config_settings_config_type, config_settings.category AS config_settings_category, config_settings.scope AS config_settings_scope, config_settings.tenant_id AS config_settings_tenant_id, config_settings.user_id AS config_settings_user_id, config_settings.session_id AS config_settings_session_id, config_settings.environment AS config_settings_environment, config_settings.encrypted AS config_settings_encrypted, config_settings.description AS config_settings_description, config_settings.tags AS config_settings_tags, config_settings.created_by AS config_settings_created_by, config_settings.updated_by AS config_settings_updated_by, config_settings.created_at AS config_settings_created_at, config_settings.updated_at AS config_settings_updated_at, config_settings.version AS config_settings_version, config_settings.previous_value AS config_settings_previous_value 
2025-07-25T22:21:50.011452920Z [error] FROM config_settings]
2025-07-25T22:21:50.011472615Z [error] (Background on this error at: https://sqlalche.me/e/20/e3q8)
2025-07-25T22:21:50.011496492Z [info] 2025-07-25 22:21:50,007 INFO sqlalchemy.engine.Engine ROLLBACK
2025-07-25T22:21:50.011518016Z [error] 2025-07-25 22:21:50,007 - sqlalchemy.engine.Engine - INFO - ROLLBACK
2025-07-25T22:21:50.094610765Z [error] Traceback (most recent call last):
2025-07-25T22:21:50.094646864Z [error]   File "<frozen runpy>", line 198, in _run_module_as_main
2025-07-25T22:21:50.094676736Z [error]   File "<frozen runpy>", line 88, in _run_code
2025-07-25T22:21:50.094711332Z [error]   File "/usr/local/lib/python3.11/site-packages/gunicorn/__main__.py", line 7, in <module>
2025-07-25T22:21:50.094732473Z [error]     run()
2025-07-25T22:21:50.094759516Z [error]   File "/usr/local/lib/python3.11/site-packages/gunicorn/app/wsgiapp.py", line 67, in run
2025-07-25T22:21:50.094783324Z [error]     WSGIApplication("%(prog)s [OPTIONS] [APP_MODULE]").run()
2025-07-25T22:21:50.094811270Z [error]   File "/usr/local/lib/python3.11/site-packages/gunicorn/app/base.py", line 236, in run
2025-07-25T22:21:50.094833509Z [error]     super().run()
2025-07-25T22:21:50.094858990Z [error]   File "/usr/local/lib/python3.11/site-packages/gunicorn/app/base.py", line 72, in run
2025-07-25T22:21:50.094878591Z [error]     Arbiter(self).run()
2025-07-25T22:21:50.094898079Z [error]     ^^^^^^^^^^^^^
2025-07-25T22:21:50.094923649Z [error]   File "/usr/local/lib/python3.11/site-packages/gunicorn/arbiter.py", line 58, in __init__
2025-07-25T22:21:50.094945282Z [error]     self.setup(app)
2025-07-25T22:21:50.094969443Z [error]   File "/usr/local/lib/python3.11/site-packages/gunicorn/arbiter.py", line 118, in setup
2025-07-25T22:21:50.094989678Z [error]     self.app.wsgi()
2025-07-25T22:21:50.095015964Z [error]   File "/usr/local/lib/python3.11/site-packages/gunicorn/app/base.py", line 67, in wsgi
2025-07-25T22:21:50.095116450Z [error]     self.callable = self.load()
2025-07-25T22:21:50.095137847Z [error]                     ^^^^^^^^^^^
2025-07-25T22:21:50.095162332Z [error]   File "/usr/local/lib/python3.11/site-packages/gunicorn/app/wsgiapp.py", line 58, in load
2025-07-25T22:21:50.095183696Z [error]     return self.load_wsgiapp()
2025-07-25T22:21:50.095202810Z [error]            ^^^^^^^^^^^^^^^^^^^
2025-07-25T22:21:50.095226588Z [error]   File "/usr/local/lib/python3.11/site-packages/gunicorn/app/wsgiapp.py", line 48, in load_wsgiapp
2025-07-25T22:21:50.095248234Z [error]     return util.import_app(self.app_uri)
2025-07-25T22:21:50.095275857Z [error]            ^^^^^^^^^^^^^^^^^^^^^^^^^^^^^
2025-07-25T22:21:50.095297872Z [error]   File "/usr/local/lib/python3.11/site-packages/gunicorn/util.py", line 371, in import_app
2025-07-25T22:21:50.095317342Z [error]     mod = importlib.import_module(module)
2025-07-25T22:21:50.095340308Z [error]           ^^^^^^^^^^^^^^^^^^^^^^^^^^^^^^^
2025-07-25T22:21:50.095362232Z [error]   File "/usr/local/lib/python3.11/importlib/__init__.py", line 126, in import_module
2025-07-25T22:21:50.095384722Z [error]     return _bootstrap._gcd_import(name[level:], package, level)
2025-07-25T22:21:50.095405288Z [error]            ^^^^^^^^^^^^^^^^^^^^^^^^^^^^^^^^^^^^^^^^^^^^^^^^^^^^
2025-07-25T22:21:50.095428200Z [error]   File "<frozen importlib._bootstrap>", line 1204, in _gcd_import
2025-07-25T22:21:50.095449520Z [error]   File "<frozen importlib._bootstrap>", line 1176, in _find_and_load
2025-07-25T22:21:50.095476350Z [error]   File "<frozen importlib._bootstrap>", line 1147, in _find_and_load_unlocked
2025-07-25T22:21:50.095498013Z [error]   File "<frozen importlib._bootstrap>", line 690, in _load_unlocked
2025-07-25T22:21:50.095520104Z [error]   File "<frozen importlib._bootstrap_external>", line 940, in exec_module
2025-07-25T22:21:50.095545678Z [error]   File "<frozen importlib._bootstrap>", line 241, in _call_with_frames_removed
2025-07-25T22:21:50.095565167Z [error]   File "/app/backend/app/main.py", line 22, in <module>
2025-07-25T22:21:50.095594802Z [error]     from .api.v1.api import api_router
2025-07-25T22:21:50.095623072Z [error]   File "/app/backend/app/api/v1/api.py", line 4, in <module>
2025-07-25T22:21:50.095642753Z [error]     from app.api import (
2025-07-25T22:21:50.095718144Z [error] ModuleNotFoundError: No module named 'app'
2025-07-25T22:21:50.779617671Z [info] Starting production server on port 8080...
2025-07-25T22:21:50.779638657Z [info] Command: python -m gunicorn backend.app.main:app -c gunicorn.conf.py
2025-07-25T22:21:50.779664307Z [info] Error starting server: Command '['python', '-m', 'gunicorn', 'backend.app.main:app', '-c', 'gunicorn.conf.py']' returned non-zero exit status 1.
2025-07-25T22:21:56.000458526Z [info] 2025-07-25 22:21:55,998 INFO sqlalchemy.engine.Engine BEGIN (implicit)
2025-07-25T22:21:56.000502415Z [error] 2025-07-25 22:21:55,998 - sqlalchemy.engine.Engine - INFO - BEGIN (implicit)
2025-07-25T22:21:56.009510863Z [info] 2025-07-25 22:21:56,005 INFO sqlalchemy.engine.Engine SELECT config_settings.id AS config_settings_id, config_settings."key" AS config_settings_key, config_settings.value AS config_settings_value, config_settings.config_type AS config_settings_config_type, config_settings.category AS config_settings_category, config_settings.scope AS config_settings_scope, config_settings.tenant_id AS config_settings_tenant_id, config_settings.user_id AS config_settings_user_id, config_settings.session_id AS config_settings_session_id, config_settings.environment AS config_settings_environment, config_settings.encrypted AS config_settings_encrypted, config_settings.description AS config_settings_description, config_settings.tags AS config_settings_tags, config_settings.created_by AS config_settings_created_by, config_settings.updated_by AS config_settings_updated_by, config_settings.created_at AS config_settings_created_at, config_settings.updated_at AS config_settings_updated_at, config_settings.version AS config_settings_version, config_settings.previous_value AS config_settings_previous_value 
2025-07-25T22:21:56.009544143Z [info] FROM config_settings
2025-07-25T22:21:56.009634763Z [error] 2025-07-25 22:21:56,005 - sqlalchemy.engine.Engine - INFO - SELECT config_settings.id AS config_settings_id, config_settings."key" AS config_settings_key, config_settings.value AS config_settings_value, config_settings.config_type AS config_settings_config_type, config_settings.category AS config_settings_category, config_settings.scope AS config_settings_scope, config_settings.tenant_id AS config_settings_tenant_id, config_settings.user_id AS config_settings_user_id, config_settings.session_id AS config_settings_session_id, config_settings.environment AS config_settings_environment, config_settings.encrypted AS config_settings_encrypted, config_settings.description AS config_settings_description, config_settings.tags AS config_settings_tags, config_settings.created_by AS config_settings_created_by, config_settings.updated_by AS config_settings_updated_by, config_settings.created_at AS config_settings_created_at, config_settings.updated_at AS config_settings_updated_at, config_settings.version AS config_settings_version, config_settings.previous_value AS config_settings_previous_value 
2025-07-25T22:21:56.009655485Z [error] FROM config_settings
2025-07-25T22:21:56.009680437Z [info] 2025-07-25 22:21:56,005 INFO sqlalchemy.engine.Engine [generated in 0.00036s] ()
2025-07-25T22:21:56.009705350Z [error] 2025-07-25 22:21:56,005 - sqlalchemy.engine.Engine - INFO - [generated in 0.00036s] ()
2025-07-25T22:21:56.009735515Z [error] 2025-07-25 22:21:56,006 - backend.app.services.config_service - ERROR - Failed to load configuration cache: (sqlite3.OperationalError) no such table: config_settings
2025-07-25T22:21:56.009816438Z [error] [SQL: SELECT config_settings.id AS config_settings_id, config_settings."key" AS config_settings_key, config_settings.value AS config_settings_value, config_settings.config_type AS config_settings_config_type, config_settings.category AS config_settings_category, config_settings.scope AS config_settings_scope, config_settings.tenant_id AS config_settings_tenant_id, config_settings.user_id AS config_settings_user_id, config_settings.session_id AS config_settings_session_id, config_settings.environment AS config_settings_environment, config_settings.encrypted AS config_settings_encrypted, config_settings.description AS config_settings_description, config_settings.tags AS config_settings_tags, config_settings.created_by AS config_settings_created_by, config_settings.updated_by AS config_settings_updated_by, config_settings.created_at AS config_settings_created_at, config_settings.updated_at AS config_settings_updated_at, config_settings.version AS config_settings_version, config_settings.previous_value AS config_settings_previous_value 
2025-07-25T22:21:56.009844121Z [error] FROM config_settings]
2025-07-25T22:21:56.009869851Z [error] (Background on this error at: https://sqlalche.me/e/20/e3q8)
2025-07-25T22:21:56.009893543Z [info] 2025-07-25 22:21:56,006 INFO sqlalchemy.engine.Engine ROLLBACK
2025-07-25T22:21:56.009917275Z [error] 2025-07-25 22:21:56,006 - sqlalchemy.engine.Engine - INFO - ROLLBACK
2025-07-25T22:21:56.094318798Z [error] Traceback (most recent call last):
2025-07-25T22:21:56.094514224Z [error]   File "<frozen runpy>", line 198, in _run_module_as_main
2025-07-25T22:21:56.094537550Z [error]   File "<frozen runpy>", line 88, in _run_code
2025-07-25T22:21:56.094568584Z [error]   File "/usr/local/lib/python3.11/site-packages/gunicorn/__main__.py", line 7, in <module>
2025-07-25T22:21:56.094587193Z [error]     run()
2025-07-25T22:21:56.094609612Z [error]   File "/usr/local/lib/python3.11/site-packages/gunicorn/app/wsgiapp.py", line 67, in run
2025-07-25T22:21:56.094633946Z [error]     WSGIApplication("%(prog)s [OPTIONS] [APP_MODULE]").run()
2025-07-25T22:21:56.094654892Z [error]   File "/usr/local/lib/python3.11/site-packages/gunicorn/app/base.py", line 236, in run
2025-07-25T22:21:56.094677672Z [error]     super().run()
2025-07-25T22:21:56.094701506Z [error]   File "/usr/local/lib/python3.11/site-packages/gunicorn/app/base.py", line 72, in run
2025-07-25T22:21:56.094722011Z [error]     Arbiter(self).run()
2025-07-25T22:21:56.094741541Z [error]     ^^^^^^^^^^^^^
2025-07-25T22:21:56.094764258Z [error]   File "/usr/local/lib/python3.11/site-packages/gunicorn/arbiter.py", line 58, in __init__
2025-07-25T22:21:56.094782272Z [error]     self.setup(app)
2025-07-25T22:21:56.094867000Z [error]   File "/usr/local/lib/python3.11/site-packages/gunicorn/arbiter.py", line 118, in setup
2025-07-25T22:21:56.094884374Z [error]     self.app.wsgi()
2025-07-25T22:21:56.094907132Z [error]   File "/usr/local/lib/python3.11/site-packages/gunicorn/app/base.py", line 67, in wsgi
2025-07-25T22:21:56.094925587Z [error]     self.callable = self.load()
2025-07-25T22:21:56.094941835Z [error]                     ^^^^^^^^^^^
2025-07-25T22:21:56.094960243Z [error]   File "/usr/local/lib/python3.11/site-packages/gunicorn/app/wsgiapp.py", line 58, in load
2025-07-25T22:21:56.094976417Z [error]     return self.load_wsgiapp()
2025-07-25T22:21:56.094995168Z [error]            ^^^^^^^^^^^^^^^^^^^
2025-07-25T22:21:56.095024675Z [error]   File "/usr/local/lib/python3.11/site-packages/gunicorn/app/wsgiapp.py", line 48, in load_wsgiapp
2025-07-25T22:21:56.095041982Z [error]     return util.import_app(self.app_uri)
2025-07-25T22:21:56.095057804Z [error]            ^^^^^^^^^^^^^^^^^^^^^^^^^^^^^
2025-07-25T22:21:56.095079273Z [error]   File "/usr/local/lib/python3.11/site-packages/gunicorn/util.py", line 371, in import_app
2025-07-25T22:21:56.095098035Z [error]     mod = importlib.import_module(module)
2025-07-25T22:21:56.095118529Z [error]           ^^^^^^^^^^^^^^^^^^^^^^^^^^^^^^^
2025-07-25T22:21:56.095163236Z [error]   File "/usr/local/lib/python3.11/importlib/__init__.py", line 126, in import_module
2025-07-25T22:21:56.095187989Z [error]     return _bootstrap._gcd_import(name[level:], package, level)
2025-07-25T22:21:56.095207250Z [error]            ^^^^^^^^^^^^^^^^^^^^^^^^^^^^^^^^^^^^^^^^^^^^^^^^^^^^
2025-07-25T22:21:56.095222501Z [error]   File "<frozen importlib._bootstrap>", line 1204, in _gcd_import
2025-07-25T22:21:56.095272401Z [error]   File "<frozen importlib._bootstrap>", line 1176, in _find_and_load
2025-07-25T22:21:56.095297027Z [error]   File "<frozen importlib._bootstrap>", line 1147, in _find_and_load_unlocked
2025-07-25T22:21:56.095317578Z [error]   File "<frozen importlib._bootstrap>", line 690, in _load_unlocked
2025-07-25T22:21:56.095336808Z [error]   File "<frozen importlib._bootstrap_external>", line 940, in exec_module
2025-07-25T22:21:56.095356564Z [error]   File "<frozen importlib._bootstrap>", line 241, in _call_with_frames_removed
2025-07-25T22:21:56.095374846Z [error]   File "/app/backend/app/main.py", line 22, in <module>
2025-07-25T22:21:56.095393727Z [error]     from .api.v1.api import api_router
2025-07-25T22:21:56.095412819Z [error]   File "/app/backend/app/api/v1/api.py", line 4, in <module>
2025-07-25T22:21:56.095429090Z [error]     from app.api import (
2025-07-25T22:21:56.095450493Z [error] ModuleNotFoundError: No module named 'app'
2025-07-25T22:21:56.814146753Z [info] Starting production server on port 8080...
2025-07-25T22:21:56.814167851Z [info] Command: python -m gunicorn backend.app.main:app -c gunicorn.conf.py
2025-07-25T22:21:56.814198173Z [info] Error starting server: Command '['python', '-m', 'gunicorn', 'backend.app.main:app', '-c', 'gunicorn.conf.py']' returned non-zero exit status 1.
2025-07-25T22:22:16.810887176Z [info] 2025-07-25 22:22:07,420 INFO sqlalchemy.engine.Engine BEGIN (implicit)
2025-07-25T22:22:16.810918730Z [error] 2025-07-25 22:22:07,420 - sqlalchemy.engine.Engine - INFO - BEGIN (implicit)
2025-07-25T22:22:16.811056193Z [info] 2025-07-25 22:22:07,426 INFO sqlalchemy.engine.Engine SELECT config_settings.id AS config_settings_id, config_settings."key" AS config_settings_key, config_settings.value AS config_settings_value, config_settings.config_type AS config_settings_config_type, config_settings.category AS config_settings_category, config_settings.scope AS config_settings_scope, config_settings.tenant_id AS config_settings_tenant_id, config_settings.user_id AS config_settings_user_id, config_settings.session_id AS config_settings_session_id, config_settings.environment AS config_settings_environment, config_settings.encrypted AS config_settings_encrypted, config_settings.description AS config_settings_description, config_settings.tags AS config_settings_tags, config_settings.created_by AS config_settings_created_by, config_settings.updated_by AS config_settings_updated_by, config_settings.created_at AS config_settings_created_at, config_settings.updated_at AS config_settings_updated_at, config_settings.version AS config_settings_version, config_settings.previous_value AS config_settings_previous_value 
2025-07-25T22:22:16.811077000Z [info] FROM config_settings
2025-07-25T22:22:16.811147491Z [error] 2025-07-25 22:22:07,426 - sqlalchemy.engine.Engine - INFO - SELECT config_settings.id AS config_settings_id, config_settings."key" AS config_settings_key, config_settings.value AS config_settings_value, config_settings.config_type AS config_settings_config_type, config_settings.category AS config_settings_category, config_settings.scope AS config_settings_scope, config_settings.tenant_id AS config_settings_tenant_id, config_settings.user_id AS config_settings_user_id, config_settings.session_id AS config_settings_session_id, config_settings.environment AS config_settings_environment, config_settings.encrypted AS config_settings_encrypted, config_settings.description AS config_settings_description, config_settings.tags AS config_settings_tags, config_settings.created_by AS config_settings_created_by, config_settings.updated_by AS config_settings_updated_by, config_settings.created_at AS config_settings_created_at, config_settings.updated_at AS config_settings_updated_at, config_settings.version AS config_settings_version, config_settings.previous_value AS config_settings_previous_value 
2025-07-25T22:22:16.811165140Z [error] FROM config_settings
2025-07-25T22:22:16.811181799Z [info] 2025-07-25 22:22:07,426 INFO sqlalchemy.engine.Engine [generated in 0.00065s] ()
2025-07-25T22:22:16.811198141Z [error] 2025-07-25 22:22:07,426 - sqlalchemy.engine.Engine - INFO - [generated in 0.00065s] ()
2025-07-25T22:22:16.811216065Z [error] 2025-07-25 22:22:07,427 - backend.app.services.config_service - ERROR - Failed to load configuration cache: (sqlite3.OperationalError) no such table: config_settings
2025-07-25T22:22:16.811265480Z [error] [SQL: SELECT config_settings.id AS config_settings_id, config_settings."key" AS config_settings_key, config_settings.value AS config_settings_value, config_settings.config_type AS config_settings_config_type, config_settings.category AS config_settings_category, config_settings.scope AS config_settings_scope, config_settings.tenant_id AS config_settings_tenant_id, config_settings.user_id AS config_settings_user_id, config_settings.session_id AS config_settings_session_id, config_settings.environment AS config_settings_environment, config_settings.encrypted AS config_settings_encrypted, config_settings.description AS config_settings_description, config_settings.tags AS config_settings_tags, config_settings.created_by AS config_settings_created_by, config_settings.updated_by AS config_settings_updated_by, config_settings.created_at AS config_settings_created_at, config_settings.updated_at AS config_settings_updated_at, config_settings.version AS config_settings_version, config_settings.previous_value AS config_settings_previous_value 
2025-07-25T22:22:16.811277760Z [error] FROM config_settings]
2025-07-25T22:22:16.811926881Z [error]   File "<frozen runpy>", line 198, in _run_module_as_main
2025-07-25T22:22:16.811951800Z [error]   File "<frozen runpy>", line 88, in _run_code
2025-07-25T22:22:16.811976245Z [error]   File "/usr/local/lib/python3.11/site-packages/gunicorn/__main__.py", line 7, in <module>
2025-07-25T22:22:16.811994956Z [error]     run()
2025-07-25T22:22:16.812013721Z [error]   File "/usr/local/lib/python3.11/site-packages/gunicorn/app/wsgiapp.py", line 67, in run
2025-07-25T22:22:16.812037200Z [error]     WSGIApplication("%(prog)s [OPTIONS] [APP_MODULE]").run()
2025-07-25T22:22:16.812204055Z [error]   File "/usr/local/lib/python3.11/site-packages/gunicorn/app/base.py", line 236, in run
2025-07-25T22:22:16.812222085Z [error]     super().run()
2025-07-25T22:22:16.812237988Z [error]   File "/usr/local/lib/python3.11/site-packages/gunicorn/app/base.py", line 72, in run
2025-07-25T22:22:16.812251887Z [error]     Arbiter(self).run()
2025-07-25T22:22:16.812264978Z [error]     ^^^^^^^^^^^^^
2025-07-25T22:22:16.812280155Z [error]   File "/usr/local/lib/python3.11/site-packages/gunicorn/arbiter.py", line 58, in __init__
2025-07-25T22:22:16.812293283Z [error]     self.setup(app)
2025-07-25T22:22:16.812308885Z [error]   File "/usr/local/lib/python3.11/site-packages/gunicorn/arbiter.py", line 118, in setup
2025-07-25T22:22:16.812321173Z [error]     self.app.wsgi()
2025-07-25T22:22:16.812337666Z [error]   File "/usr/local/lib/python3.11/site-packages/gunicorn/app/base.py", line 67, in wsgi
2025-07-25T22:22:16.812351084Z [error]     self.callable = self.load()
2025-07-25T22:22:16.812365981Z [error]                     ^^^^^^^^^^^
2025-07-25T22:22:16.812380383Z [error]   File "/usr/local/lib/python3.11/site-packages/gunicorn/app/wsgiapp.py", line 58, in load
2025-07-25T22:22:16.812393489Z [error]     return self.load_wsgiapp()
2025-07-25T22:22:16.812405756Z [error]            ^^^^^^^^^^^^^^^^^^^
2025-07-25T22:22:16.812420855Z [error]   File "/usr/local/lib/python3.11/site-packages/gunicorn/app/wsgiapp.py", line 48, in load_wsgiapp
2025-07-25T22:22:16.812434991Z [error]     return util.import_app(self.app_uri)
2025-07-25T22:22:16.812450391Z [error]            ^^^^^^^^^^^^^^^^^^^^^^^^^^^^^
2025-07-25T22:22:16.812469644Z [error]   File "/usr/local/lib/python3.11/site-packages/gunicorn/util.py", line 371, in import_app
2025-07-25T22:22:16.812486897Z [error]     mod = importlib.import_module(module)
2025-07-25T22:22:16.812505006Z [error]           ^^^^^^^^^^^^^^^^^^^^^^^^^^^^^^^
2025-07-25T22:22:16.812526200Z [error]   File "/usr/local/lib/python3.11/importlib/__init__.py", line 126, in import_module
2025-07-25T22:22:16.812543126Z [error]     return _bootstrap._gcd_import(name[level:], package, level)
2025-07-25T22:22:16.812557436Z [error]            ^^^^^^^^^^^^^^^^^^^^^^^^^^^^^^^^^^^^^^^^^^^^^^^^^^^^
2025-07-25T22:22:16.812570861Z [error]   File "<frozen importlib._bootstrap>", line 1204, in _gcd_import
2025-07-25T22:22:16.812585382Z [error]   File "<frozen importlib._bootstrap>", line 1176, in _find_and_load
2025-07-25T22:22:16.812600722Z [error]   File "<frozen importlib._bootstrap>", line 1147, in _find_and_load_unlocked
2025-07-25T22:22:16.812619930Z [error]   File "<frozen importlib._bootstrap>", line 690, in _load_unlocked
2025-07-25T22:22:16.812634503Z [error]   File "<frozen importlib._bootstrap_external>", line 940, in exec_module
2025-07-25T22:22:16.812654194Z [error]   File "<frozen importlib._bootstrap>", line 241, in _call_with_frames_removed
2025-07-25T22:22:16.812667987Z [error]   File "/app/backend/app/main.py", line 22, in <module>
2025-07-25T22:22:16.812683595Z [error]     from .api.v1.api import api_router
2025-07-25T22:22:16.812702409Z [error]   File "/app/backend/app/api/v1/api.py", line 4, in <module>
2025-07-25T22:22:16.812714778Z [error]     from app.api import (
2025-07-25T22:22:16.812728150Z [error] ModuleNotFoundError: No module named 'app'
2025-07-25T22:22:16.812743159Z [info] Starting production server on port 8080...
2025-07-25T22:22:16.812758777Z [info] Command: python -m gunicorn backend.app.main:app -c gunicorn.conf.py
2025-07-25T22:22:16.812779740Z [info] Error starting server: Command '['python', '-m', 'gunicorn', 'backend.app.main:app', '-c', 'gunicorn.conf.py']' returned non-zero exit status 1.
2025-07-25T22:22:16.812794450Z [info] 2025-07-25 22:22:13,788 INFO sqlalchemy.engine.Engine BEGIN (implicit)
2025-07-25T22:22:16.812916933Z [error] (Background on this error at: https://sqlalche.me/e/20/e3q8)
2025-07-25T22:22:16.813061398Z [info] 2025-07-25 22:22:07,427 INFO sqlalchemy.engine.Engine ROLLBACK
2025-07-25T22:22:16.813088986Z [error] 2025-07-25 22:22:07,427 - sqlalchemy.engine.Engine - INFO - ROLLBACK
2025-07-25T22:22:16.813117184Z [error] Traceback (most recent call last):
2025-07-25T22:22:16.813238717Z [info] 2025-07-25 22:22:13,793 INFO sqlalchemy.engine.Engine SELECT config_settings.id AS config_settings_id, config_settings."key" AS config_settings_key, config_settings.value AS config_settings_value, config_settings.config_type AS config_settings_config_type, config_settings.category AS config_settings_category, config_settings.scope AS config_settings_scope, config_settings.tenant_id AS config_settings_tenant_id, config_settings.user_id AS config_settings_user_id, config_settings.session_id AS config_settings_session_id, config_settings.environment AS config_settings_environment, config_settings.encrypted AS config_settings_encrypted, config_settings.description AS config_settings_description, config_settings.tags AS config_settings_tags, config_settings.created_by AS config_settings_created_by, config_settings.updated_by AS config_settings_updated_by, config_settings.created_at AS config_settings_created_at, config_settings.updated_at AS config_settings_updated_at, config_settings.version AS config_settings_version, config_settings.previous_value AS config_settings_previous_value 
2025-07-25T22:22:16.813254363Z [info] FROM config_settings
2025-07-25T22:22:16.813273981Z [info] 2025-07-25 22:22:13,793 INFO sqlalchemy.engine.Engine [generated in 0.00044s] ()
2025-07-25T22:22:16.813290390Z [info] 2025-07-25 22:22:13,794 INFO sqlalchemy.engine.Engine ROLLBACK
2025-07-25T22:22:16.813309152Z [error] 2025-07-25 22:22:13,788 - sqlalchemy.engine.Engine - INFO - BEGIN (implicit)
2025-07-25T22:22:16.813382727Z [error] 2025-07-25 22:22:13,793 - sqlalchemy.engine.Engine - INFO - SELECT config_settings.id AS config_settings_id, config_settings."key" AS config_settings_key, config_settings.value AS config_settings_value, config_settings.config_type AS config_settings_config_type, config_settings.category AS config_settings_category, config_settings.scope AS config_settings_scope, config_settings.tenant_id AS config_settings_tenant_id, config_settings.user_id AS config_settings_user_id, config_settings.session_id AS config_settings_session_id, config_settings.environment AS config_settings_environment, config_settings.encrypted AS config_settings_encrypted, config_settings.description AS config_settings_description, config_settings.tags AS config_settings_tags, config_settings.created_by AS config_settings_created_by, config_settings.updated_by AS config_settings_updated_by, config_settings.created_at AS config_settings_created_at, config_settings.updated_at AS config_settings_updated_at, config_settings.version AS config_settings_version, config_settings.previous_value AS config_settings_previous_value 
2025-07-25T22:22:16.827732078Z [error] FROM config_settings
2025-07-25T22:22:16.829081490Z [error] 2025-07-25 22:22:13,793 - sqlalchemy.engine.Engine - INFO - [generated in 0.00044s] ()
2025-07-25T22:22:16.829146967Z [error] 2025-07-25 22:22:13,794 - backend.app.services.config_service - ERROR - Failed to load configuration cache: (sqlite3.OperationalError) no such table: config_settings
2025-07-25T22:22:16.829231431Z [error] [SQL: SELECT config_settings.id AS config_settings_id, config_settings."key" AS config_settings_key, config_settings.value AS config_settings_value, config_settings.config_type AS config_settings_config_type, config_settings.category AS config_settings_category, config_settings.scope AS config_settings_scope, config_settings.tenant_id AS config_settings_tenant_id, config_settings.user_id AS config_settings_user_id, config_settings.session_id AS config_settings_session_id, config_settings.environment AS config_settings_environment, config_settings.encrypted AS config_settings_encrypted, config_settings.description AS config_settings_description, config_settings.tags AS config_settings_tags, config_settings.created_by AS config_settings_created_by, config_settings.updated_by AS config_settings_updated_by, config_settings.created_at AS config_settings_created_at, config_settings.updated_at AS config_settings_updated_at, config_settings.version AS config_settings_version, config_settings.previous_value AS config_settings_previous_value 
2025-07-25T22:22:16.829252739Z [error] FROM config_settings]
2025-07-25T22:22:16.829274181Z [error] (Background on this error at: https://sqlalche.me/e/20/e3q8)
2025-07-25T22:22:16.829293665Z [error] 2025-07-25 22:22:13,794 - sqlalchemy.engine.Engine - INFO - ROLLBACK
2025-07-25T22:22:16.829313546Z [error] Traceback (most recent call last):
2025-07-25T22:22:16.829333861Z [error]   File "<frozen runpy>", line 198, in _run_module_as_main
2025-07-25T22:22:16.829351484Z [error]   File "<frozen runpy>", line 88, in _run_code
2025-07-25T22:22:16.829371479Z [error]   File "/usr/local/lib/python3.11/site-packages/gunicorn/__main__.py", line 7, in <module>
2025-07-25T22:22:16.829390766Z [error]     run()
2025-07-25T22:22:16.829411847Z [error]   File "/usr/local/lib/python3.11/site-packages/gunicorn/app/wsgiapp.py", line 67, in run
2025-07-25T22:22:16.829431664Z [error]     WSGIApplication("%(prog)s [OPTIONS] [APP_MODULE]").run()
2025-07-25T22:22:16.829450853Z [error]   File "/usr/local/lib/python3.11/site-packages/gunicorn/app/base.py", line 236, in run
2025-07-25T22:22:16.829469290Z [error]     super().run()
2025-07-25T22:22:16.829498408Z [error]   File "/usr/local/lib/python3.11/site-packages/gunicorn/app/base.py", line 72, in run
2025-07-25T22:22:16.829515337Z [error]     Arbiter(self).run()
2025-07-25T22:22:16.829531467Z [error]     ^^^^^^^^^^^^^
2025-07-25T22:22:16.829551400Z [error]   File "/usr/local/lib/python3.11/site-packages/gunicorn/arbiter.py", line 58, in __init__
2025-07-25T22:22:16.829569544Z [error]     self.setup(app)
2025-07-25T22:22:16.829589061Z [error]   File "/usr/local/lib/python3.11/site-packages/gunicorn/arbiter.py", line 118, in setup
2025-07-25T22:22:16.829606663Z [error]     self.app.wsgi()
2025-07-25T22:22:16.829626583Z [error]   File "/usr/local/lib/python3.11/site-packages/gunicorn/app/base.py", line 67, in wsgi
2025-07-25T22:22:16.829645359Z [error]     self.callable = self.load()
2025-07-25T22:22:16.829664464Z [error]                     ^^^^^^^^^^^
2025-07-25T22:22:16.829684031Z [error]   File "/usr/local/lib/python3.11/site-packages/gunicorn/app/wsgiapp.py", line 58, in load
2025-07-25T22:22:16.829702481Z [error]     return self.load_wsgiapp()
2025-07-25T22:22:16.829726962Z [error]            ^^^^^^^^^^^^^^^^^^^
2025-07-25T22:22:16.829749197Z [error]   File "/usr/local/lib/python3.11/site-packages/gunicorn/app/wsgiapp.py", line 48, in load_wsgiapp
2025-07-25T22:22:16.829770083Z [error]     return util.import_app(self.app_uri)
2025-07-25T22:22:16.829787424Z [error]            ^^^^^^^^^^^^^^^^^^^^^^^^^^^^^
2025-07-25T22:22:16.829809867Z [error]   File "/usr/local/lib/python3.11/site-packages/gunicorn/util.py", line 371, in import_app
2025-07-25T22:22:16.829830526Z [error]     mod = importlib.import_module(module)
2025-07-25T22:22:16.829851443Z [error]           ^^^^^^^^^^^^^^^^^^^^^^^^^^^^^^^
2025-07-25T22:22:16.829871615Z [error]   File "/usr/local/lib/python3.11/importlib/__init__.py", line 126, in import_module
2025-07-25T22:22:16.829890564Z [error]     return _bootstrap._gcd_import(name[level:], package, level)
2025-07-25T22:22:16.829913656Z [error]            ^^^^^^^^^^^^^^^^^^^^^^^^^^^^^^^^^^^^^^^^^^^^^^^^^^^^
2025-07-25T22:22:16.829933763Z [error]   File "<frozen importlib._bootstrap>", line 1204, in _gcd_import
2025-07-25T22:22:16.829953392Z [error]   File "<frozen importlib._bootstrap>", line 1176, in _find_and_load
2025-07-25T22:22:16.829973178Z [error]   File "<frozen importlib._bootstrap>", line 1147, in _find_and_load_unlocked
2025-07-25T22:22:16.830684798Z [error]   File "<frozen importlib._bootstrap>", line 690, in _load_unlocked
2025-07-25T22:22:16.830737362Z [error]   File "<frozen importlib._bootstrap_external>", line 940, in exec_module
2025-07-25T22:22:16.830762710Z [error]   File "<frozen importlib._bootstrap>", line 241, in _call_with_frames_removed
2025-07-25T22:22:16.830787635Z [error]   File "/app/backend/app/main.py", line 22, in <module>
2025-07-25T22:22:16.830805860Z [error]     from .api.v1.api import api_router
2025-07-25T22:22:16.830825092Z [error]   File "/app/backend/app/api/v1/api.py", line 4, in <module>
2025-07-25T22:22:16.830938317Z [error]     from app.api import (
2025-07-25T22:22:16.830964876Z [error] ModuleNotFoundError: No module named 'app'
2025-07-25T22:22:16.830984302Z [info] Starting production server on port 8080...
2025-07-25T22:22:16.831010532Z [info] Command: python -m gunicorn backend.app.main:app -c gunicorn.conf.py
2025-07-25T22:22:16.831047137Z [info] Error starting server: Command '['python', '-m', 'gunicorn', 'backend.app.main:app', '-c', 'gunicorn.conf.py']' returned non-zero exit status 1.
2025-07-25T22:22:20.467554526Z [info] 2025-07-25 22:22:20,465 INFO sqlalchemy.engine.Engine BEGIN (implicit)
2025-07-25T22:22:20.467590653Z [error] 2025-07-25 22:22:20,465 - sqlalchemy.engine.Engine - INFO - BEGIN (implicit)
2025-07-25T22:22:20.478752932Z [info] 2025-07-25 22:22:20,470 INFO sqlalchemy.engine.Engine SELECT config_settings.id AS config_settings_id, config_settings."key" AS config_settings_key, config_settings.value AS config_settings_value, config_settings.config_type AS config_settings_config_type, config_settings.category AS config_settings_category, config_settings.scope AS config_settings_scope, config_settings.tenant_id AS config_settings_tenant_id, config_settings.user_id AS config_settings_user_id, config_settings.session_id AS config_settings_session_id, config_settings.environment AS config_settings_environment, config_settings.encrypted AS config_settings_encrypted, config_settings.description AS config_settings_description, config_settings.tags AS config_settings_tags, config_settings.created_by AS config_settings_created_by, config_settings.updated_by AS config_settings_updated_by, config_settings.created_at AS config_settings_created_at, config_settings.updated_at AS config_settings_updated_at, config_settings.version AS config_settings_version, config_settings.previous_value AS config_settings_previous_value 
2025-07-25T22:22:20.478786452Z [info] FROM config_settings
2025-07-25T22:22:20.478812408Z [info] 2025-07-25 22:22:20,471 INFO sqlalchemy.engine.Engine [generated in 0.00042s] ()
2025-07-25T22:22:20.478894033Z [error] 2025-07-25 22:22:20,470 - sqlalchemy.engine.Engine - INFO - SELECT config_settings.id AS config_settings_id, config_settings."key" AS config_settings_key, config_settings.value AS config_settings_value, config_settings.config_type AS config_settings_config_type, config_settings.category AS config_settings_category, config_settings.scope AS config_settings_scope, config_settings.tenant_id AS config_settings_tenant_id, config_settings.user_id AS config_settings_user_id, config_settings.session_id AS config_settings_session_id, config_settings.environment AS config_settings_environment, config_settings.encrypted AS config_settings_encrypted, config_settings.description AS config_settings_description, config_settings.tags AS config_settings_tags, config_settings.created_by AS config_settings_created_by, config_settings.updated_by AS config_settings_updated_by, config_settings.created_at AS config_settings_created_at, config_settings.updated_at AS config_settings_updated_at, config_settings.version AS config_settings_version, config_settings.previous_value AS config_settings_previous_value 
2025-07-25T22:22:20.478915391Z [error] FROM config_settings
2025-07-25T22:22:20.478938399Z [error] 2025-07-25 22:22:20,471 - sqlalchemy.engine.Engine - INFO - [generated in 0.00042s] ()
2025-07-25T22:22:20.478967017Z [error] 2025-07-25 22:22:20,471 - backend.app.services.config_service - ERROR - Failed to load configuration cache: (sqlite3.OperationalError) no such table: config_settings
2025-07-25T22:22:20.479041836Z [error] [SQL: SELECT config_settings.id AS config_settings_id, config_settings."key" AS config_settings_key, config_settings.value AS config_settings_value, config_settings.config_type AS config_settings_config_type, config_settings.category AS config_settings_category, config_settings.scope AS config_settings_scope, config_settings.tenant_id AS config_settings_tenant_id, config_settings.user_id AS config_settings_user_id, config_settings.session_id AS config_settings_session_id, config_settings.environment AS config_settings_environment, config_settings.encrypted AS config_settings_encrypted, config_settings.description AS config_settings_description, config_settings.tags AS config_settings_tags, config_settings.created_by AS config_settings_created_by, config_settings.updated_by AS config_settings_updated_by, config_settings.created_at AS config_settings_created_at, config_settings.updated_at AS config_settings_updated_at, config_settings.version AS config_settings_version, config_settings.previous_value AS config_settings_previous_value 
2025-07-25T22:22:20.479061987Z [error] FROM config_settings]
2025-07-25T22:22:20.479086153Z [error] (Background on this error at: https://sqlalche.me/e/20/e3q8)
2025-07-25T22:22:20.479111381Z [error] 2025-07-25 22:22:20,471 - sqlalchemy.engine.Engine - INFO - ROLLBACK
2025-07-25T22:22:20.479133621Z [info] 2025-07-25 22:22:20,471 INFO sqlalchemy.engine.Engine ROLLBACK
2025-07-25T22:22:20.550922836Z [error] Traceback (most recent call last):
2025-07-25T22:22:20.550954353Z [error]   File "<frozen runpy>", line 198, in _run_module_as_main
2025-07-25T22:22:20.550973818Z [error]   File "<frozen runpy>", line 88, in _run_code
2025-07-25T22:22:20.550996754Z [error]   File "/usr/local/lib/python3.11/site-packages/gunicorn/__main__.py", line 7, in <module>
2025-07-25T22:22:20.551179497Z [error]     run()
2025-07-25T22:22:20.551204277Z [error]   File "/usr/local/lib/python3.11/site-packages/gunicorn/app/wsgiapp.py", line 67, in run
2025-07-25T22:22:20.551222401Z [error]     WSGIApplication("%(prog)s [OPTIONS] [APP_MODULE]").run()
2025-07-25T22:22:20.551243521Z [error]   File "/usr/local/lib/python3.11/site-packages/gunicorn/app/base.py", line 236, in run
2025-07-25T22:22:20.551262551Z [error]     super().run()
2025-07-25T22:22:20.551282488Z [error]   File "/usr/local/lib/python3.11/site-packages/gunicorn/app/base.py", line 72, in run
2025-07-25T22:22:20.551298195Z [error]     Arbiter(self).run()
2025-07-25T22:22:20.551314069Z [error]     ^^^^^^^^^^^^^
2025-07-25T22:22:20.551335529Z [error]   File "/usr/local/lib/python3.11/site-packages/gunicorn/arbiter.py", line 58, in __init__
2025-07-25T22:22:20.551351552Z [error]     self.setup(app)
2025-07-25T22:22:20.551370487Z [error]   File "/usr/local/lib/python3.11/site-packages/gunicorn/arbiter.py", line 118, in setup
2025-07-25T22:22:20.551384670Z [error]     self.app.wsgi()
2025-07-25T22:22:20.551408640Z [error]   File "/usr/local/lib/python3.11/site-packages/gunicorn/app/base.py", line 67, in wsgi
2025-07-25T22:22:20.551569234Z [error]     self.callable = self.load()
2025-07-25T22:22:20.551589565Z [error]                     ^^^^^^^^^^^
2025-07-25T22:22:20.551613306Z [error]   File "/usr/local/lib/python3.11/site-packages/gunicorn/app/wsgiapp.py", line 58, in load
2025-07-25T22:22:20.551630002Z [error]     return self.load_wsgiapp()
2025-07-25T22:22:20.551647748Z [error]            ^^^^^^^^^^^^^^^^^^^
2025-07-25T22:22:20.551667912Z [error]   File "/usr/local/lib/python3.11/site-packages/gunicorn/app/wsgiapp.py", line 48, in load_wsgiapp
2025-07-25T22:22:20.551685546Z [error]     return util.import_app(self.app_uri)
2025-07-25T22:22:20.551703825Z [error]            ^^^^^^^^^^^^^^^^^^^^^^^^^^^^^
2025-07-25T22:22:20.551721630Z [error]   File "/usr/local/lib/python3.11/site-packages/gunicorn/util.py", line 371, in import_app
2025-07-25T22:22:20.551738445Z [error]     mod = importlib.import_module(module)
2025-07-25T22:22:20.551755000Z [error]           ^^^^^^^^^^^^^^^^^^^^^^^^^^^^^^^
2025-07-25T22:22:20.551772627Z [error]   File "/usr/local/lib/python3.11/importlib/__init__.py", line 126, in import_module
2025-07-25T22:22:20.551790356Z [error]     return _bootstrap._gcd_import(name[level:], package, level)
2025-07-25T22:22:20.551808721Z [error]            ^^^^^^^^^^^^^^^^^^^^^^^^^^^^^^^^^^^^^^^^^^^^^^^^^^^^
2025-07-25T22:22:20.551826581Z [error]   File "<frozen importlib._bootstrap>", line 1204, in _gcd_import
2025-07-25T22:22:20.553405946Z [error]   File "<frozen importlib._bootstrap>", line 1176, in _find_and_load
2025-07-25T22:22:20.553433138Z [error]   File "<frozen importlib._bootstrap>", line 1147, in _find_and_load_unlocked
2025-07-25T22:22:20.553451697Z [error]   File "<frozen importlib._bootstrap>", line 690, in _load_unlocked
2025-07-25T22:22:20.553473491Z [error]   File "<frozen importlib._bootstrap_external>", line 940, in exec_module
2025-07-25T22:22:20.553493144Z [error]   File "<frozen importlib._bootstrap>", line 241, in _call_with_frames_removed
2025-07-25T22:22:20.553510239Z [error]   File "/app/backend/app/main.py", line 22, in <module>
2025-07-25T22:22:20.553528725Z [error]     from .api.v1.api import api_router
2025-07-25T22:22:20.553547093Z [error]   File "/app/backend/app/api/v1/api.py", line 4, in <module>
2025-07-25T22:22:20.553562617Z [error]     from app.api import (
2025-07-25T22:22:20.553581778Z [error] ModuleNotFoundError: No module named 'app'
2025-07-25T22:22:21.198024769Z [info] Starting production server on port 8080...
2025-07-25T22:22:21.198079265Z [info] Command: python -m gunicorn backend.app.main:app -c gunicorn.conf.py
2025-07-25T22:22:21.198109669Z [info] Error starting server: Command '['python', '-m', 'gunicorn', 'backend.app.main:app', '-c', 'gunicorn.conf.py']' returned non-zero exit status 1.